Workbook

Sheet READ ME
B1: PHASE 3 — COVERAGE & HOTSPOT MATRIX
B3: WHAT THIS IS
B4: 32 disclosure topics (rows) scored against 31 columns: 29 scored instruments — with VSME split into Basic + Comprehensive, so 30 instrument columns — plus ISSF (tuna opt-in) and the CSRD/ESRS baseline. The full Phase 2 landscape is 37 instruments; the 8 that are catalogued but not scored are listed on the 'Scope log' sheet.
B6: CODING SCALE — 0 / 1 / 2
B7: 2 = the framework bindingly requires the entity to achieve, comply with, certify, report on or disclose at least one datapoint of the topic. Binding conformity counts equally with binding disclosure.
B8: 1 = touched: references the topic but imposes no binding datapoint requirement.
B9: 0 = absent, or maps only to datapoints outside the 32-row universe. (blank = not yet coded)
B10: The score is INDEPENDENT of obligation locus — an indirect instrument (e.g. CSDDD, SFDR) can still score 2. Locus is recorded separately.
B11: Every 1 and every 2 has a row in the 'Justifications log' (clause reference + source + datapoint ID).
B13: COMPUTED COLUMNS (auto)
B14: Breadth Σ = sum of all scores for the topic — the volume of demand.
B15: Reg / Cust / Inv / NGO = 1 if any instrument of that stakeholder type scores >0 on the topic.
... B43: 4. SELF-ASSESSMENT & RATINGS: instruments scored on published structure (EcoVadis, SAQ) cap at 1; external ratings that score the firm without its input (MSCI, Sustainalytics, DJSI) are not scored at all — see the Scope log.

Sheet Coverage matrix
A1: 28-TOPIC × FRAMEWORK COVERAGE MATRIX — Phase 3 hotspot analysis | AL1: Stage thresholds → | AQ1: breadth≥ | AR1: 12
E2: Necessity tier | F2: Tier 1 | G2: Tier 1 | H2: Tier 1 | I2: Tier 1 | J2: Tier 1 | K2: Tier 1 | L2: Tier 1 | M2: Tier 1 | N2: Tier 1 | O2: Tier 1 | P2: Tier 1 | Q2: Tier 1 | R2: Tier 2 | S2: Tier 2 | T2: Tier 2 | U2: Tier 2 | V2: Tier 2 | W2: Tier 2 | X2: Tier 2 | Y2: Tier 3 | Z2: Tier 3 | AA2: Tier 3 | AB2: Tier 3 | AC2: Tier 3 | AD2: Tier 3 | AE2: Tier 4 | AF2: Tier 3 | AG2: Tier 3 | AH2: Tier 4 | AI2: Tier 4 | AJ2: Tier 4 | AK2: Tier 3 | AQ2: conv≥ | AR2: 3
E3: Stakeholder | F3: Regulator | G3: Regulator | H3: Regulator | I3: Regulator | J3: Regulator | K3: Regulator | L3: Regulator | M3: Regulator | N3: Regulator | O3: Regulator | P3: Regulator | Q3: Regulator | R3: Customer | S3: Customer | T3: Customer | U3: Customer | V3: Customer | W3: Customer | X3: Customer | Y3: Customer | Z3: Customer | AA3: Customer | AB3: Customer | AC3: Investor | AD3: Investor | AE3: Investor | AF3: Industry / NGO | AG3: Industry / NGO | AH3: Industry / NGO | AI3: Industry / NGO | AJ3: Industry / NGO | AK3: Customer | AQ3: indep wt cutoff | AR3: 0.5
E4: Obligation | F4: Direct | G4: Direct | H4: Direct | I4: Direct | J4: Direct | K4: Direct | L4: Direct | M4: Direct | N4: Direct | O4: Direct | P4: Direct | Q4: Direct | R4: Direct | S4: Direct | T4: Direct | U4: Direct | V4: Direct | W4: Direct | X4: Direct | Y4: Indirect | Z4: Indirect | AA4: Direct | AB4: Direct | AC4: Indirect | AD4: Indirect | AE4: Direct | AF4: Direct | AG4: Direct | AH4: Direct | AI4: Direct | AJ4: Direct | AK4: Indirect
A5: # | B5: Topic / DR | C5: ESG | E5: Tier | F5: Fisheries Control Regulation (2023/2842) | G5: IUU Regulation (1005/2008) | H5: CMO marketing standards (1379/2013) | I5: PPWR (2025/40) | J5: OSH Framework Directive (89/391/EEC) | K5: Working Time Directive (2003/88/EC) | L5: Forced Labour Regulation (2024/3015) | M5: EUDR (2023/1115) | N5: EmpCo Directive (2024/825) | O5: F-gas Regulation (2024/573) | P5: Whistleblowing Directive (2019/1937) | Q5: Pay Transparency Directive (2023/970) | R5: MSC | S5: ASC | T5: GSA BAP | U5: GLOBALG.A.P. Aquaculture | V5: Friend of the Sea | W5: SAQ from Sedex (follow by SMETA) | X5: EcoVadis | Y5: CSDDD (2024/1760) | Z5: CDP | AA5: VSME-Basic | AB5: VSME-Comprehensive | AC5: SFDR (2019/2088) | AD5: IFRS S1/S2 (ISSB) | AE5: TNFD | AF5: GDST | AG5: GRI Standards (incl. GRI 13) | AH5: ISSF | AI5: SBTi | AJ5: UN Global Compact | AK5: CSRD / ESRS [BASELINE — excluded from sums] | AL5: Breadth Σ | AM5: Reg | AN5: Cust | AO5: Inv | AP5: NGO | AQ5: Conv (0-4) | AR5: Stage | AS5: Topic system | AT5: System
A6: 1 | B6: E1-3 | C6: E | D6: Actions and resources in relation to climate change policies | E6: T1 | F6: 0 | G6: 0 | H6: 0 | I6: 0 | J6: 0 | K6: 0 | L6: 0 | M6: 0 | N6: 0 | O6: 1 | P6: 0 | Q6: 0 | R6: 0 | S6: 0 | T6: 0 | U6: 0 | V6: 0 | W6: 0 | X6: 0 | Y6: 0 | Z6: 1 | AA6: 0 | AB6: 1 | AC6: 0 | AD6: 2 | AE6: 0 | AF6: 0 | AG6: 1 | AH6: 0 | AI6: 1 | AJ6: 0 | AL6: =SUMPRODUCT(F6:AJ6,$F$45:$AJ$45) -> 7 | AM6: =IF(SUMPRODUCT(--(F6:AJ6>0),--($F$45:$AJ$45=1),--($F$3:$AJ$3="Regulator"))>0,1,0) -> 1 | AN6: =IF(SUMPRODUCT(--(F6:AJ6>0),--($F$45:$AJ$45=1),--($F$3:$AJ$3="Customer"))>0,1,0) -> 1 | AO6: =IF(SUMPRODUCT(--(F6:AJ6>0),--($F$45:$AJ$45=1),--($F$3:$AJ$3="Investor"))>0,1,0) -> 1 | AP6: =IF(SUMPRODUCT(--(F6:AJ6>0),--($F$45:$AJ$45=1),--($F$3:$AJ$3="Industry / NGO"))>0,1,0) -> 1 | AQ6: =SUM(AM6:AP6) -> 4 | AR6: =IF(AND(OR(AS6="Wild",AS6="Aqua"),NOT(OR($C$51="both",$C$51=LOWER(AS6)))),"n/a — system",IF(AQ6=0,"—",IF(AND(AQ6>=$AR$2,AL6>=$AR$1),"1 — Build first",IF(AQ6>=3,"2 — Next","3 — Monitor")))) -> 2 — Next
A7: 2 | B7: E1-4 | C7: E | D7: Targets related to climate change mitigation and adaptation | E7: T1 | F7: 0 | G7: 0 | H7: 0 | I7: 0 | J7: 0 | K7: 0 | L7: 0 | M7: 0 | N7: 0 | O7: 0 | P7: 0 | Q7: 0 | R7: 0 | S7: 0 | T7: 0 | U7: 0 | V7: 0 | W7: 0 | X7: 0 | Y7: 0 | Z7: 1 | AA7: 0 | AB7: 2 | AC7: 0 | AD7: 2 | AE7: 0 | AF7: 0 | AG7: 1 | AH7: 0 | AI7: 2 | AJ7: 0 | AL7: =SUMPRODUCT(F7:AJ7,$F$45:$AJ$45) -> 8 | AM7: =IF(SUMPRODUCT(--(F7:AJ7>0),--($F$45:$AJ$45=1),--($F$3:$AJ$3="Regulator"))>0,1,0) -> 0 | AN7: =IF(SUMPRODUCT(--(F7:AJ7>0),--($F$45:$AJ$45=1),--($F$3:$AJ$3="Customer"))>0,1,0) -> 1 | AO7: =IF(SUMPRODUCT(--(F7:AJ7>0),--($F$45:$AJ$45=1),--($F$3:$AJ$3="Investor"))>0,1,0) -> 1 | AP7: =IF(SUMPRODUCT(--(F7:AJ7>0),--($F$45:$AJ$45=1),--($F$3:$AJ$3="Industry / NGO"))>0,1,0) -> 1 | AQ7: =SUM(AM7:AP7) -> 3 | AR7: =IF(AND(OR(AS7="Wild",AS7="Aqua"),NOT(OR($C$51="both",$C$51=LOWER(AS7)))),"n/a — system",IF(AQ7=0,"—",IF(AND(AQ7>=$AR$2,AL7>=$AR$1),"1 — Build first",IF(AQ7>=3,"2 — Next","3 — Monitor")))) -> 2 — Next
A8: 3 | B8: E1-5 | C8: E | D8: Energy consumption and mix | E8: T1 | F8: 0 | G8: 0 | H8: 0 | I8: 0 | J8: 0 | K8: 0 | L8: 0 | M8: 0 | N8: 0 | O8: 0 | P8: 0 | Q8: 0 | R8: 0 | S8: 0 | T8: 0 | U8: 0 | V8: 0 | W8: 1 | X8: 1 | Y8: 0 | Z8: 2 | AA8: 2 | AB8: 0 | AC8: 2 | AD8: 1 | AE8: 0 | AF8: 0 | AG8: 2 | AH8: 0 | AI8: 0 | AJ8: 1 | AL8: =SUMPRODUCT(F8:AJ8,$F$45:$AJ$45) -> 12 | AM8: =IF(SUMPRODUCT(--(F8:AJ8>0),--($F$45:$AJ$45=1),--($F$3:$AJ$3="Regulator"))>0,1,0) -> 0 | AN8: =IF(SUMPRODUCT(--(F8:AJ8>0),--($F$45:$AJ$45=1),--($F$3:$AJ$3="Customer"))>0,1,0) -> 1 | AO8: =IF(SUMPRODUCT(--(F8:AJ8>0),--($F$45:$AJ$45=1),--($F$3:$AJ$3="Investor"))>0,1,0) -> 1 | AP8: =IF(SUMPRODUCT(--(F8:AJ8>0),--($F$45:$AJ$45=1),--($F$3:$AJ$3="Industry / NGO"))>0,1,0) -> 1 | AQ8: =SUM(AM8:AP8) -> 3 | AR8: =IF(AND(OR(AS8="Wild",AS8="Aqua"),NOT(OR($C$51="both",$C$51=LOWER(AS8)))),"n/a — system",IF(AQ8=0,"—",IF(AND(AQ8>=$AR$2,AL8>=$AR$1),"1 — Build first",IF(AQ8>=3,"2 — Next","3 — Monitor")))) -> 1 — Build first
A9: 4 | B9: E1-6 | C9: E | D9: Gross scopes 1, 2, 3 and total GHG emissions | E9: T1 | F9: 0 | G9: 0 | H9: 0 | I9: 0 | J9: 0 | K9: 0 | L9: 0 | M9: 0 | N9: 0 | O9: 2 | P9: 0 | Q9: 0 | R9: 0 | S9: 0 | T9: 0 | U9: 0 | V9: 0 | W9: 1 | X9: 1 | Y9: 0 | Z9: 2 | AA9: 2 | AB9: 0 | AC9: 2 | AD9: 2 | AE9: 0 | AF9: 0 | AG9: 2 | AH9: 0 | AI9: 1 | AJ9: 0 | AL9: =SUMPRODUCT(F9:AJ9,$F$45:$AJ$45) -> 15 | AM9: =IF(SUMPRODUCT(--(F9:AJ9>0),--($F$45:$AJ$45=1),--($F$3:$AJ$3="Regulator"))>0,1,0) -> 1 | AN9: =IF(SUMPRODUCT(--(F9:AJ9>0),--($F$45:$AJ$45=1),--($F$3:$AJ$3="Customer"))>0,1,0) -> 1 | AO9: =IF(SUMPRODUCT(--(F9:AJ9>0),--($F$45:$AJ$45=1),--($F$3:$AJ$3="Investor"))>0,1,0) -> 1 | AP9: =IF(SUMPRODUCT(--(F9:AJ9>0),--($F$45:$AJ$45=1),--($F$3:$AJ$3="Industry / NGO"))>0,1,0) -> 1 | AQ9: =SUM(AM9:AP9) -> 4 | AR9: =IF(AND(OR(AS9="Wild",AS9="Aqua"),NOT(OR($C$51="both",$C$51=LOWER(AS9)))),"n/a — system",IF(AQ9=0,"—",IF(AND(AQ9>=$AR$2,AL9>=$AR$1),"1 — Build first",IF(AQ9>=3,"2 — Next","3 — Monitor")))) -> 1 — Build first
A10: 5 | B10: E3-1 | C10: E | D10: Policies related to water and marine resources | E10: T1 | F10: 0 | G10: 0 | H10: 0 | I10: 0 | J10: 0 | K10: 0 | L10: 0 | M10: 0 | N10: 0 | O10: 0 | P10: 0 | Q10: 0 | R10: 0 | S10: 2 | T10: 1 | U10: 0 | V10: 0 | X10: 0 | Y10: 1 | Z10: 1 | AA10: 0 | AB10: 0 | AC10: 0 | AD10: 0 | AE10: 0 | AF10: 0 | AG10: 1 | AH10: 0 | AI10: 0 | AJ10: 0 | AL10: =SUMPRODUCT(F10:AJ10,$F$45:$AJ$45) -> 6 | AM10: =IF(SUMPRODUCT(--(F10:AJ10>0),--($F$45:$AJ$45=1),--($F$3:$AJ$3="Regulator"))>0,1,0) -> 0 | AN10: =IF(SUMPRODUCT(--(F10:AJ10>0),--($F$45:$AJ$45=1),--($F$3:$AJ$3="Customer"))>0,1,0) -> 1 | AO10: =IF(SUMPRODUCT(--(F10:AJ10>0),--($F$45:$AJ$45=1),--($F$3:$AJ$3="Investor"))>0,1,0) -> 0 | AP10: =IF(SUMPRODUCT(--(F10:AJ10>0),--($F$45:$AJ$45=1),--($F$3:$AJ$3="Industry / NGO"))>0,1,0) -> 1 | AQ10: =SUM(AM10:AP10) -> 2 | AR10: =IF(AND(OR(AS10="Wild",AS10="Aqua"),NOT(OR($C$51="both",$C$51=LOWER(AS10)))),"n/a — system",IF(AQ10=0,"—",IF(AND(AQ10>=$AR$2,AL10>=$AR$1),"1 — Build first",IF(AQ10>=3,"2 — Next","3 — Monitor")))) -> 3 — Monitor
A11: 6 | B11: E3-2 | C11: E | D11: Actions and resources related to water and marine resources | E11: T1 | F11: 0 | G11: 0 | H11: 0 | I11: 0 | J11: 0 | K11: 0 | L11: 0 | M11: 0 | N11: 0 | O11: 0 | P11: 0 | Q11: 0 | R11: 0 | S11: 0 | T11: 0 | U11: 0 | V11: 0 | W11: 0 | X11: 0 | Y11: 1 | Z11: 0 | AA11: 0 | AB11: 0 | AC11: 0 | AD11: 0 | AE11: 0 | AF11: 0 | AG11: 0 | AH11: 0 | AI11: 0 | AJ11: 0 | AL11: =SUMPRODUCT(F11:AJ11,$F$45:$AJ$45) -> 1 | AM11: =IF(SUMPRODUCT(--(F11:AJ11>0),--($F$45:$AJ$45=1),--($F$3:$AJ$3="Regulator"))>0,1,0) -> 0 | AN11: =IF(SUMPRODUCT(--(F11:AJ11>0),--($F$45:$AJ$45=1),--($F$3:$AJ$3="Customer"))>0,1,0) -> 1 | AO11: =IF(SUMPRODUCT(--(F11:AJ11>0),--($F$45:$AJ$45=1),--($F$3:$AJ$3="Investor"))>0,1,0) -> 0 | AP11: =IF(SUMPRODUCT(--(F11:AJ11>0),--($F$45:$AJ$45=1),--($F$3:$AJ$3="Industry / NGO"))>0,1,0) -> 0 | AQ11: =SUM(AM11:AP11) -> 1 | AR11: =IF(AND(OR(AS11="Wild",AS11="Aqua"),NOT(OR($C$51="both",$C$51=LOWER(AS11)))),"n/a — system",IF(AQ11=0,"—",IF(AND(AQ11>=$AR$2,AL11>=$AR$1),"1 — Build first",IF(AQ11>=3,"2 — Next","3 — Monitor")))) -> 3 — Monitor
A12: 7 | B12: E3-3 | C12: E | D12: Targets related to water and marine resources | E12: T1 | F12: 0 | G12: 0 | H12: 0 | I12: 0 | J12: 0 | K12: 0 | L12: 0 | M12: 0 | N12: 0 | O12: 0 | P12: 0 | Q12: 0 | R12: 0 | S12: 0 | T12: 0 | U12: 0 | V12: 0 | W12: 0 | X12: 0 | Y12: 1 | Z12: 2 | AA12: 0 | AB12: 0 | AC12: 0 | AD12: 0 | AE12: 0 | AF12: 0 | AG12: 0 | AH12: 0 | AI12: 0 | AJ12: 0 | AL12: =SUMPRODUCT(F12:AJ12,$F$45:$AJ$45) -> 3 | AM12: =IF(SUMPRODUCT(--(F12:AJ12>0),--($F$45:$AJ$45=1),--($F$3:$AJ$3="Regulator"))>0,1,0) -> 0 | AN12: =IF(SUMPRODUCT(--(F12:AJ12>0),--($F$45:$AJ$45=1),--($F$3:$AJ$3="Customer"))>0,1,0) -> 1 | AO12: =IF(SUMPRODUCT(--(F12:AJ12>0),--($F$45:$AJ$45=1),--($F$3:$AJ$3="Investor"))>0,1,0) -> 0 | AP12: =IF(SUMPRODUCT(--(F12:AJ12>0),--($F$45:$AJ$45=1),--($F$3:$AJ$3="Industry / NGO"))>0,1,0) -> 0 | AQ12: =SUM(AM12:AP12) -> 1 | AR12: =IF(AND(OR(AS12="Wild",AS12="Aqua"),NOT(OR($C$51="both",$C$51=LOWER(AS12)))),"n/a — system",IF(AQ12=0,"—",IF(AND(AQ12>=$AR$2,AL12>=$AR$1),"1 — Build first",IF(AQ12>=3,"2 — Next","3 — Monitor")))) -> 3 — Monitor
A13: 8 | B13: E3-4 | C13: E | D13: Water consumption | E13: T1 | F13: 0 | G13: 0 | H13: 0 | I13: 0 | J13: 0 | K13: 0 | L13: 0 | M13: 0 | N13: 0 | O13: 0 | P13: 0 | Q13: 0 | R13: 0 | S13: 2 | T13: 2 | U13: 1 | V13: 0 | W13: 1 | X13: 1 | Y13: 1 | Z13: 2 | AA13: 2 | AB13: 0 | AC13: 0 | AD13: 0 | AE13: 2 | AF13: 0 | AG13: 2 | AH13: 0 | AI13: 0 | AJ13: 0 | AL13: =SUMPRODUCT(F13:AJ13,$F$45:$AJ$45) -> 16 | AM13: =IF(SUMPRODUCT(--(F13:AJ13>0),--($F$45:$AJ$45=1),--($F$3:$AJ$3="Regulator"))>0,1,0) -> 0 | AN13: =IF(SUMPRODUCT(--(F13:AJ13>0),--($F$45:$AJ$45=1),--($F$3:$AJ$3="Customer"))>0,1,0) -> 1 | AO13: =IF(SUMPRODUCT(--(F13:AJ13>0),--($F$45:$AJ$45=1),--($F$3:$AJ$3="Investor"))>0,1,0) -> 1 | AP13: =IF(SUMPRODUCT(--(F13:AJ13>0),--($F$45:$AJ$45=1),--($F$3:$AJ$3="Industry / NGO"))>0,1,0) -> 1 | AQ13: =SUM(AM13:AP13) -> 3 | AR13: =IF(AND(OR(AS13="Wild",AS13="Aqua"),NOT(OR($C$51="both",$C$51=LOWER(AS13)))),"n/a — system",IF(AQ13=0,"—",IF(AND(AQ13>=$AR$2,AL13>=$AR$1),"1 — Build first",IF(AQ13>=3,"2 — Next","3 — Monitor")))) -> 1 — Build first
A14: 9 | B14: E5-2 | C14: E | D14: Actions and resources related to resource use and circular economy | E14: T1 | F14: 0 | G14: 0 | H14: 0 | I14: 2 | J14: 0 | K14: 0 | L14: 0 | M14: 0 | N14: 0 | O14: 0 | P14: 0 | Q14: 0 | R14: 0 | S14: 0 | T14: 0 | U14: 0 | V14: 0 | W14: 0 | X14: 0 | Y14: 0 | Z14: 0 | AA14: 1 | AB14: 0 | AC14: 0 | AD14: 0 | AE14: 0 | AF14: 0 | AG14: 1 | AH14: 0 | AI14: 0 | AJ14: 0 | AL14: =SUMPRODUCT(F14:AJ14,$F$45:$AJ$45) -> 4 | AM14: =IF(SUMPRODUCT(--(F14:AJ14>0),--($F$45:$AJ$45=1),--($F$3:$AJ$3="Regulator"))>0,1,0) -> 1 | AN14: =IF(SUMPRODUCT(--(F14:AJ14>0),--($F$45:$AJ$45=1),--($F$3:$AJ$3="Customer"))>0,1,0) -> 1 | AO14: =IF(SUMPRODUCT(--(F14:AJ14>0),--($F$45:$AJ$45=1),--($F$3:$AJ$3="Investor"))>0,1,0) -> 0 | AP14: =IF(SUMPRODUCT(--(F14:AJ14>0),--($F$45:$AJ$45=1),--($F$3:$AJ$3="Industry / NGO"))>0,1,0) -> 1 | AQ14: =SUM(AM14:AP14) -> 3 | AR14: =IF(AND(OR(AS14="Wild",AS14="Aqua"),NOT(OR($C$51="both",$C$51=LOWER(AS14)))),"n/a — system",IF(AQ14=0,"—",IF(AND(AQ14>=$AR$2,AL14>=$AR$1),"1 — Build first",IF(AQ14>=3,"2 — Next","3 — Monitor")))) -> 2 — Next
A15: 10 | B15: E5-4 | C15: E | D15: Resource inflows | E15: T1 | F15: 0 | G15: 0 | H15: 0 | I15: 2 | J15: 0 | K15: 0 | L15: 0 | M15: 0 | N15: 0 | O15: 0 | P15: 0 | Q15: 0 | R15: 0 | S15: 0 | T15: 0 | U15: 0 | V15: 0 | W15: 0 | X15: 0 | Y15: 0 | Z15: 0 | AA15: 1 | AB15: 0 | AC15: 0 | AD15: 0 | AE15: 0 | AF15: 0 | AG15: 1 | AH15: 0 | AI15: 0 | AJ15: 0 | AL15: =SUMPRODUCT(F15:AJ15,$F$45:$AJ$45) -> 4 | AM15: =IF(SUMPRODUCT(--(F15:AJ15>0),--($F$45:$AJ$45=1),--($F$3:$AJ$3="Regulator"))>0,1,0) -> 1 | AN15: =IF(SUMPRODUCT(--(F15:AJ15>0),--($F$45:$AJ$45=1),--($F$3:$AJ$3="Customer"))>0,1,0) -> 1 | AO15: =IF(SUMPRODUCT(--(F15:AJ15>0),--($F$45:$AJ$45=1),--($F$3:$AJ$3="Investor"))>0,1,0) -> 0 | AP15: =IF(SUMPRODUCT(--(F15:AJ15>0),--($F$45:$AJ$45=1),--($F$3:$AJ$3="Industry / NGO"))>0,1,0) -> 1 | AQ15: =SUM(AM15:AP15) -> 3 | AR15: =IF(AND(OR(AS15="Wild",AS15="Aqua"),NOT(OR($C$51="both",$C$51=LOWER(AS15)))),"n/a — system",IF(AQ15=0,"—",IF(AND(AQ15>=$AR$2,AL15>=$AR$1),"1 — Build first",IF(AQ15>=3,"2 — Next","3 — Monitor")))) -> 2 — Next
A16: 11 | B16: E5-5 | C16: E | D16: Resource outflows | E16: T1 | F16: 0 | G16: 0 | H16: 0 | I16: 2 | J16: 0 | K16: 0 | L16: 0 | M16: 0 | N16: 0 | O16: 0 | P16: 0 | Q16: 0 | R16: 0 | S16: 1 | T16: 0 | U16: 0 | V16: 0 | W16: 1 | X16: 1 | Y16: 0 | Z16: 0 | AA16: 2 | AB16: 0 | AC16: 2 | AD16: 0 | AE16: 1 | AF16: 0 | AG16: 2 | AH16: 0 | AI16: 0 | AJ16: 0 | AL16: =SUMPRODUCT(F16:AJ16,$F$45:$AJ$45) -> 12 | AM16: =IF(SUMPRODUCT(--(F16:AJ16>0),--($F$45:$AJ$45=1),--($F$3:$AJ$3="Regulator"))>0,1,0) -> 1 | AN16: =IF(SUMPRODUCT(--(F16:AJ16>0),--($F$45:$AJ$45=1),--($F$3:$AJ$3="Customer"))>0,1,0) -> 1 | AO16: =IF(SUMPRODUCT(--(F16:AJ16>0),--($F$45:$AJ$45=1),--($F$3:$AJ$3="Investor"))>0,1,0) -> 1 | AP16: =IF(SUMPRODUCT(--(F16:AJ16>0),--($F$45:$AJ$45=1),--($F$3:$AJ$3="Industry / NGO"))>0,1,0) -> 1 | AQ16: =SUM(AM16:AP16) -> 4 | AR16: =IF(AND(OR(AS16="Wild",AS16="Aqua"),NOT(OR($C$51="both",$C$51=LOWER(AS16)))),"n/a — system",IF(AQ16=0,"—",IF(AND(AQ16>=$AR$2,AL16>=$AR$1),"1 — Build first",IF(AQ16>=3,"2 — Next","3 — Monitor")))) -> 1 — Build first
A17: 12 | B17: G1-1 | C17: G | D17: Corporate culture and business conduct policies and corporate culture | E17: T1 | F17: 0 | G17: 0 | H17: 0 | I17: 0 | J17: 0 | K17: 0 | L17: 0 | M17: 0 | N17: 0 | O17: 0 | P17: 2 | Q17: 0 | R17: 0 | S17: 0 | T17: 0 | U17: 0 | V17: 0 | W17: 1 | X17: 1 | Y17: 1 | Z17: 0 | AA17: 0 | AB17: 0 | AC17: 2 | AD17: 0 | AE17: 0 | AF17: 0 | AG17: 1 | AH17: 0 | AI17: 0 | AJ17: 1 | AL17: =SUMPRODUCT(F17:AJ17,$F$45:$AJ$45) -> 9 | AM17: =IF(SUMPRODUCT(--(F17:AJ17>0),--($F$45:$AJ$45=1),--($F$3:$AJ$3="Regulator"))>0,1,0) -> 1 | AN17: =IF(SUMPRODUCT(--(F17:AJ17>0),--($F$45:$AJ$45=1),--($F$3:$AJ$3="Customer"))>0,1,0) -> 1 | AO17: =IF(SUMPRODUCT(--(F17:AJ17>0),--($F$45:$AJ$45=1),--($F$3:$AJ$3="Investor"))>0,1,0) -> 1 | AP17: =IF(SUMPRODUCT(--(F17:AJ17>0),--($F$45:$AJ$45=1),--($F$3:$AJ$3="Industry / NGO"))>0,1,0) -> 1 | AQ17: =SUM(AM17:AP17) -> 4 | AR17: =IF(AND(OR(AS17="Wild",AS17="Aqua"),NOT(OR($C$51="both",$C$51=LOWER(AS17)))),"n/a — system",IF(AQ17=0,"—",IF(AND(AQ17>=$AR$2,AL17>=$AR$1),"1 — Build first",IF(AQ17>=3,"2 — Next","3 — Monitor")))) -> 2 — Next
A18: 13 | B18: G1-3 | C18: G | D18: Prevention and detection of corruption and bribery | E18: T1 | F18: 0 | G18: 0 | H18: 0 | I18: 0 | J18: 0 | K18: 0 | L18: 0 | M18: 0 | N18: 0 | O18: 0 | P18: 0 | Q18: 0 | R18: 0 | S18: 0 | T18: 0 | U18: 0 | V18: 0 | W18: 1 | X18: 1 | Y18: 0 | Z18: 0 | AA18: 0 | AB18: 0 | AC18: 0 | AD18: 0 | AE18: 0 | AF18: 0 | AG18: 2 | AH18: 0 | AI18: 0 | AJ18: 1 | AL18: =SUMPRODUCT(F18:AJ18,$F$45:$AJ$45) -> 5 | AM18: =IF(SUMPRODUCT(--(F18:AJ18>0),--($F$45:$AJ$45=1),--($F$3:$AJ$3="Regulator"))>0,1,0) -> 0 | AN18: =IF(SUMPRODUCT(--(F18:AJ18>0),--($F$45:$AJ$45=1),--($F$3:$AJ$3="Customer"))>0,1,0) -> 1 | AO18: =IF(SUMPRODUCT(--(F18:AJ18>0),--($F$45:$AJ$45=1),--($F$3:$AJ$3="Investor"))>0,1,0) -> 0 | AP18: =IF(SUMPRODUCT(--(F18:AJ18>0),--($F$45:$AJ$45=1),--($F$3:$AJ$3="Industry / NGO"))>0,1,0) -> 1 | AQ18: =SUM(AM18:AP18) -> 2 | AR18: =IF(AND(OR(AS18="Wild",AS18="Aqua"),NOT(OR($C$51="both",$C$51=LOWER(AS18)))),"n/a — system",IF(AQ18=0,"—",IF(AND(AQ18>=$AR$2,AL18>=$AR$1),"1 — Build first",IF(AQ18>=3,"2 — Next","3 — Monitor")))) -> 3 — Monitor
A19: 14 | B19: G1-4 | C19: G | D19: Confirmed incidents of corruption or bribery | E19: T1 | F19: 0 | G19: 0 | H19: 0 | I19: 0 | J19: 0 | K19: 0 | L19: 0 | M19: 0 | N19: 0 | O19: 0 | P19: 0 | Q19: 0 | R19: 0 | S19: 0 | T19: 0 | U19: 0 | V19: 0 | W19: 0 | X19: 0 | Y19: 0 | Z19: 0 | AA19: 2 | AB19: 0 | AC19: 0 | AD19: 0 | AE19: 0 | AF19: 0 | AG19: 2 | AH19: 0 | AI19: 0 | AJ19: 0 | AL19: =SUMPRODUCT(F19:AJ19,$F$45:$AJ$45) -> 4 | AM19: =IF(SUMPRODUCT(--(F19:AJ19>0),--($F$45:$AJ$45=1),--($F$3:$AJ$3="Regulator"))>0,1,0) -> 0 | AN19: =IF(SUMPRODUCT(--(F19:AJ19>0),--($F$45:$AJ$45=1),--($F$3:$AJ$3="Customer"))>0,1,0) -> 1 | AO19: =IF(SUMPRODUCT(--(F19:AJ19>0),--($F$45:$AJ$45=1),--($F$3:$AJ$3="Investor"))>0,1,0) -> 0 | AP19: =IF(SUMPRODUCT(--(F19:AJ19>0),--($F$45:$AJ$45=1),--($F$3:$AJ$3="Industry / NGO"))>0,1,0) -> 1 | AQ19: =SUM(AM19:AP19) -> 2 | AR19: =IF(AND(OR(AS19="Wild",AS19="Aqua"),NOT(OR($C$51="both",$C$51=LOWER(AS19)))),"n/a — system",IF(AQ19=0,"—",IF(AND(AQ19>=$AR$2,AL19>=$AR$1),"1 — Build first",IF(AQ19>=3,"2 — Next","3 — Monitor")))) -> 3 — Monitor
A20: 15 | B20: G1-5 | C20: G | D20: Political influence and lobbying activities | E20: T1 | F20: 0 | G20: 0 | H20: 0 | I20: 0 | J20: 0 | K20: 0 | L20: 0 | M20: 0 | N20: 0 | O20: 0 | P20: 0 | Q20: 0 | R20: 0 | S20: 0 | T20: 0 | U20: 0 | V20: 0 | W20: 0 | X20: 0 | Y20: 0 | Z20: 0 | AA20: 0 | AB20: 0 | AC20: 0 | AD20: 0 | AE20: 0 | AF20: 0 | AG20: 2 | AH20: 0 | AI20: 0 | AJ20: 0 | AL20: =SUMPRODUCT(F20:AJ20,$F$45:$AJ$45) -> 2 | AM20: =IF(SUMPRODUCT(--(F20:AJ20>0),--($F$45:$AJ$45=1),--($F$3:$AJ$3="Regulator"))>0,1,0) -> 0 | AN20: =IF(SUMPRODUCT(--(F20:AJ20>0),--($F$45:$AJ$45=1),--($F$3:$AJ$3="Customer"))>0,1,0) -> 0 | AO20: =IF(SUMPRODUCT(--(F20:AJ20>0),--($F$45:$AJ$45=1),--($F$3:$AJ$3="Investor"))>0,1,0) -> 0 | AP20: =IF(SUMPRODUCT(--(F20:AJ20>0),--($F$45:$AJ$45=1),--($F$3:$AJ$3="Industry / NGO"))>0,1,0) -> 1 | AQ20: =SUM(AM20:AP20) -> 1 | AR20: =IF(AND(OR(AS20="Wild",AS20="Aqua"),NOT(OR($C$51="both",$C$51=LOWER(AS20)))),"n/a — system",IF(AQ20=0,"—",IF(AND(AQ20>=$AR$2,AL20>=$AR$1),"1 — Build first",IF(AQ20>=3,"2 — Next","3 — Monitor")))) -> 3 — Monitor
A21: 16 | B21: S1-1 | C21: S | D21: Policies related to own workforce | E21: T1 | F21: 0 | G21: 0 | H21: 0 | I21: 0 | J21: 0 | K21: 0 | L21: 0 | M21: 0 | N21: 0 | O21: 0 | P21: 0 | Q21: 0 | R21: 0 | S21: 0 | T21: 0 | U21: 0 | V21: 0 | W21: 2 | X21: 1 | Y21: 2 | Z21: 0 | AA21: 0 | AB21: 2 | AC21: 0 | AD21: 0 | AE21: 0 | AF21: 0 | AG21: 1 | AH21: 0 | AI21: 0 | AJ21: 1 | AL21: =SUMPRODUCT(F21:AJ21,$F$45:$AJ$45) -> 9 | AM21: =IF(SUMPRODUCT(--(F21:AJ21>0),--($F$45:$AJ$45=1),--($F$3:$AJ$3="Regulator"))>0,1,0) -> 0 | AN21: =IF(SUMPRODUCT(--(F21:AJ21>0),--($F$45:$AJ$45=1),--($F$3:$AJ$3="Customer"))>0,1,0) -> 1 | AO21: =IF(SUMPRODUCT(--(F21:AJ21>0),--($F$45:$AJ$45=1),--($F$3:$AJ$3="Investor"))>0,1,0) -> 0 | AP21: =IF(SUMPRODUCT(--(F21:AJ21>0),--($F$45:$AJ$45=1),--($F$3:$AJ$3="Industry / NGO"))>0,1,0) -> 1 | AQ21: =SUM(AM21:AP21) -> 2 | AR21: =IF(AND(OR(AS21="Wild",AS21="Aqua"),NOT(OR($C$51="both",$C$51=LOWER(AS21)))),"n/a — system",IF(AQ21=0,"—",IF(AND(AQ21>=$AR$2,AL21>=$AR$1),"1 — Build first",IF(AQ21>=3,"2 — Next","3 — Monitor")))) -> 3 — Monitor
A22: 17 | B22: S1-14 | C22: S | D22: Health and safety metrics | E22: T1 | F22: 0 | G22: 0 | H22: 0 | I22: 0 | J22: 2 | K22: 0 | L22: 0 | M22: 0 | N22: 0 | O22: 0 | P22: 0 | Q22: 0 | R22: 0 | S22: 0 | T22: 2 | U22: 0 | V22: 0 | W22: 2 | X22: 1 | Y22: 1 | Z22: 0 | AA22: 2 | AB22: 0 | AC22: 0 | AD22: 0 | AE22: 0 | AF22: 0 | AG22: 2 | AH22: 0 | AI22: 0 | AJ22: 0 | AL22: =SUMPRODUCT(F22:AJ22,$F$45:$AJ$45) -> 12 | AM22: =IF(SUMPRODUCT(--(F22:AJ22>0),--($F$45:$AJ$45=1),--($F$3:$AJ$3="Regulator"))>0,1,0) -> 1 | AN22: =IF(SUMPRODUCT(--(F22:AJ22>0),--($F$45:$AJ$45=1),--($F$3:$AJ$3="Customer"))>0,1,0) -> 1 | AO22: =IF(SUMPRODUCT(--(F22:AJ22>0),--($F$45:$AJ$45=1),--($F$3:$AJ$3="Investor"))>0,1,0) -> 0 | AP22: =IF(SUMPRODUCT(--(F22:AJ22>0),--($F$45:$AJ$45=1),--($F$3:$AJ$3="Industry / NGO"))>0,1,0) -> 1 | AQ22: =SUM(AM22:AP22) -> 3 | AR22: =IF(AND(OR(AS22="Wild",AS22="Aqua"),NOT(OR($C$51="both",$C$51=LOWER(AS22)))),"n/a — system",IF(AQ22=0,"—",IF(AND(AQ22>=$AR$2,AL22>=$AR$1),"1 — Build first",IF(AQ22>=3,"2 — Next","3 — Monitor")))) -> 1 — Build first
... A31: 26 | B31: S2-3 | C31: S | D31: Processes to remediate negative impacts and channels for value chain workers to raise concerns | E31: T1 | F31: 0 | G31: 0 | H31: 0 | I31: 0 | J31: 0 | K31: 0 | L31: 0 | M31: 0 | N31: 0 | O31: 0 | P31: 1 | Q31: 0 | R31: 0 | S31: 0 | T31: 0 | U31: 0 | V31: 0 | W31: 0 | X31: 0 | Y31: 2 | Z31: 0 | AA31: 0 | AB31: 0 | AC31: 0 | AD31: 0 | AE31: 0 | AF31: 0 | AG31: 0 | AH31: 0 | AI31: 0 | AJ31: 0 | AL31: =SUMPRODUCT(F31:AJ31,$F$45:$AJ$45) -> 3 | AM31: =IF(SUMPRODUCT(--(F31:AJ31>0),--($F$45:$AJ$45=1),--($F$3:$AJ$3="Regulator"))>0,1,0) -> 1 | AN31: =IF(SUMPRODUCT(--(F31:AJ31>0),--($F$45:$AJ$45=1),--($F$3:$AJ$3="Customer"))>0,1,0) -> 1 | AO31: =IF(SUMPRODUCT(--(F31:AJ31>0),--($F$45:$AJ$45=1),--($F$3:$AJ$3="Investor"))>0,1,0) -> 0 | AP31: =IF(SUMPRODUCT(--(F31:AJ31>0),--($F$45:$AJ$45=1),--($F$3:$AJ$3="Industry / NGO"))>0,1,0) -> 0 | AQ31: =SUM(AM31:AP31) -> 2 | AR31: =IF(AND(OR(AS31="Wild",AS31="Aqua"),NOT(OR($C$51="both",$C$51=LOWER(AS31)))),"n/a — system",IF(AQ31=0,"—",IF(AND(AQ31>=$AR$2,AL31>=$AR$1),"1 — Build first",IF(AQ31>=3,"2 — Next","3 — Monitor")))) -> 3 — Monitor
A32: 27 | B32: Biodiversity & ecosystems (E4) | C32: E | E32: T2 | F32: 0 | G32: 0 | H32: 0 | I32: 0 | J32: 0 | K32: 0 | L32: 0 | M32: 2 | N32: 0 | O32: 0 | P32: 0 | Q32: 0 | R32: 2 | S32: 2 | T32: 1 | U32: 1 | V32: 1 | W32: 0 | X32: 0 | Y32: 2 | Z32: 1 | AA32: 1 | AB32: 0 | AC32: 2 | AD32: 0 | AE32: 2 | AF32: 0 | AG32: 2 | AH32: 2 | AI32: 0 | AJ32: 0 | AL32: =SUMPRODUCT(F32:AJ32,$F$45:$AJ$45) -> 19 | AM32: =IF(SUMPRODUCT(--(F32:AJ32>0),--($F$45:$AJ$45=1),--($F$3:$AJ$3="Regulator"))>0,1,0) -> 1 | AN32: =IF(SUMPRODUCT(--(F32:AJ32>0),--($F$45:$AJ$45=1),--($F$3:$AJ$3="Customer"))>0,1,0) -> 1 | AO32: =IF(SUMPRODUCT(--(F32:AJ32>0),--($F$45:$AJ$45=1),--($F$3:$AJ$3="Investor"))>0,1,0) -> 1 | AP32: =IF(SUMPRODUCT(--(F32:AJ32>0),--($F$45:$AJ$45=1),--($F$3:$AJ$3="Industry / NGO"))>0,1,0) -> 1 | AQ32: =SUM(AM32:AP32) -> 4 | AR32: =IF(AND(OR(AS32="Wild",AS32="Aqua"),NOT(OR($C$51="both",$C$51=LOWER(AS32)))),"n/a — system",IF(AQ32=0,"—",IF(AND(AQ32>=$AR$2,AL32>=$AR$1),"1 — Build first",IF(AQ32>=3,"2 — Next","3 — Monitor")))) -> 1 — Build first
A33: 28 | B33: Consumers & end-users (S4) | C33: S | E33: T2 | F33: 0 | G33: 0 | H33: 1 | I33: 0 | J33: 0 | K33: 0 | L33: 0 | M33: 0 | N33: 1 | O33: 0 | P33: 0 | Q33: 0 | R33: 0 | S33: 0 | T33: 2 | U33: 2 | V33: 0 | W33: 0 | X33: 0 | Y33: 0 | Z33: 0 | AA33: 0 | AB33: 0 | AC33: 0 | AD33: 0 | AE33: 0 | AF33: 0 | AG33: 2 | AH33: 0 | AI33: 0 | AJ33: 0 | AL33: =SUMPRODUCT(F33:AJ33,$F$45:$AJ$45) -> 8 | AM33: =IF(SUMPRODUCT(--(F33:AJ33>0),--($F$45:$AJ$45=1),--($F$3:$AJ$3="Regulator"))>0,1,0) -> 1 | AN33: =IF(SUMPRODUCT(--(F33:AJ33>0),--($F$45:$AJ$45=1),--($F$3:$AJ$3="Customer"))>0,1,0) -> 1 | AO33: =IF(SUMPRODUCT(--(F33:AJ33>0),--($F$45:$AJ$45=1),--($F$3:$AJ$3="Investor"))>0,1,0) -> 0 | AP33: =IF(SUMPRODUCT(--(F33:AJ33>0),--($F$45:$AJ$45=1),--($F$3:$AJ$3="Industry / NGO"))>0,1,0) -> 1 | AQ33: =SUM(AM33:AP33) -> 3 | AR33: =IF(AND(OR(AS33="Wild",AS33="Aqua"),NOT(OR($C$51="both",$C$51=LOWER(AS33)))),"n/a — system",IF(AQ33=0,"—",IF(AND(AQ33>=$AR$2,AL33>=$AR$1),"1 — Build first",IF(AQ33>=3,"2 — Next","3 — Monitor")))) -> 2 — Next
A34: G1 | B34: Supply-chain traceability (chain of custody) | C34: G | E34: GAP | F34: 2 | G34: 2 | H34: 2 | I34: 0 | J34: 0 | K34: 0 | L34: 0 | M34: 1 | N34: 0 | O34: 0 | P34: 0 | Q34: 0 | R34: 2 | S34: 2 | T34: 2 | U34: 2 | V34: 2 | W34: 0 | X34: 0 | Y34: 1 | Z34: 0 | AA34: 0 | AB34: 0 | AC34: 0 | AD34: 0 | AE34: 0 | AF34: 2 | AG34: 2 | AH34: 2 | AI34: 0 | AJ34: 0 | AL34: =SUMPRODUCT(F34:AJ34,$F$45:$AJ$45) -> 22 | AM34: =IF(SUMPRODUCT(--(F34:AJ34>0),--($F$45:$AJ$45=1),--($F$3:$AJ$3="Regulator"))>0,1,0) -> 1 | AN34: =IF(SUMPRODUCT(--(F34:AJ34>0),--($F$45:$AJ$45=1),--($F$3:$AJ$3="Customer"))>0,1,0) -> 1 | AO34: =IF(SUMPRODUCT(--(F34:AJ34>0),--($F$45:$AJ$45=1),--($F$3:$AJ$3="Investor"))>0,1,0) -> 0 | AP34: =IF(SUMPRODUCT(--(F34:AJ34>0),--($F$45:$AJ$45=1),--($F$3:$AJ$3="Industry / NGO"))>0,1,0) -> 1 | AQ34: =SUM(AM34:AP34) -> 3 | AR34: =IF(AND(OR(AS34="Wild",AS34="Aqua"),NOT(OR($C$51="both",$C$51=LOWER(AS34)))),"n/a — system",IF(AQ34=0,"—",IF(AND(AQ34>=$AR$2,AL34>=$AR$1),"1 — Build first",IF(AQ34>=3,"2 — Next","3 — Monitor")))) -> 1 — Build first | AS34: Both | AT34: Both
A35: G2 | B35: Wild-stock status / sustainable wild sourcing | C35: E | E35: GAP | F35: 1 | G35: 1 | H35: 1 | I35: 0 | J35: 0 | K35: 0 | L35: 0 | M35: 0 | N35: 0 | O35: 0 | P35: 0 | Q35: 0 | R35: 2 | S35: 0 | T35: 0 | U35: 0 | V35: 2 | W35: 0 | X35: 0 | Y35: 1 | Z35: 0 | AA35: 0 | AB35: 0 | AC35: 0 | AD35: 0 | AE35: 1 | AF35: 1 | AG35: 2 | AH35: 2 | AI35: 0 | AJ35: 0 | AL35: =SUMPRODUCT(F35:AJ35,$F$45:$AJ$45) -> 12 | AM35: =IF(SUMPRODUCT(--(F35:AJ35>0),--($F$45:$AJ$45=1),--($F$3:$AJ$3="Regulator"))>0,1,0) -> 1 | AN35: =IF(SUMPRODUCT(--(F35:AJ35>0),--($F$45:$AJ$45=1),--($F$3:$AJ$3="Customer"))>0,1,0) -> 1 | AO35: =IF(SUMPRODUCT(--(F35:AJ35>0),--($F$45:$AJ$45=1),--($F$3:$AJ$3="Investor"))>0,1,0) -> 1 | AP35: =IF(SUMPRODUCT(--(F35:AJ35>0),--($F$45:$AJ$45=1),--($F$3:$AJ$3="Industry / NGO"))>0,1,0) -> 1 | AQ35: =SUM(AM35:AP35) -> 4 | AR35: =IF(AND(OR(AS35="Wild",AS35="Aqua"),NOT(OR($C$51="both",$C$51=LOWER(AS35)))),"n/a — system",IF(AQ35=0,"—",IF(AND(AQ35>=$AR$2,AL35>=$AR$1),"1 — Build first",IF(AQ35>=3,"2 — Next","3 — Monitor")))) -> 1 — Build first | AS35: Wild | AT35: Wild
A36: G3 | B36: Feed & marine ingredients sourcing | C36: E | E36: GAP | F36: 0 | G36: 0 | H36: 0 | I36: 0 | J36: 0 | K36: 0 | L36: 0 | M36: 1 | N36: 0 | O36: 0 | P36: 0 | Q36: 0 | R36: 0 | S36: 2 | T36: 2 | U36: 1 | V36: 1 | W36: 0 | X36: 0 | Y36: 1 | Z36: 0 | AA36: 0 | AB36: 0 | AC36: 0 | AD36: 0 | AE36: 0 | AF36: 0 | AG36: 2 | AH36: 0 | AI36: 0 | AJ36: 0 | AL36: =SUMPRODUCT(F36:AJ36,$F$45:$AJ$45) -> 10 | AM36: =IF(SUMPRODUCT(--(F36:AJ36>0),--($F$45:$AJ$45=1),--($F$3:$AJ$3="Regulator"))>0,1,0) -> 1 | AN36: =IF(SUMPRODUCT(--(F36:AJ36>0),--($F$45:$AJ$45=1),--($F$3:$AJ$3="Customer"))>0,1,0) -> 1 | AO36: =IF(SUMPRODUCT(--(F36:AJ36>0),--($F$45:$AJ$45=1),--($F$3:$AJ$3="Investor"))>0,1,0) -> 0 | AP36: =IF(SUMPRODUCT(--(F36:AJ36>0),--($F$45:$AJ$45=1),--($F$3:$AJ$3="Industry / NGO"))>0,1,0) -> 1 | AQ36: =SUM(AM36:AP36) -> 3 | AR36: =IF(AND(OR(AS36="Wild",AS36="Aqua"),NOT(OR($C$51="both",$C$51=LOWER(AS36)))),"n/a — system",IF(AQ36=0,"—",IF(AND(AQ36>=$AR$2,AL36>=$AR$1),"1 — Build first",IF(AQ36>=3,"2 — Next","3 — Monitor")))) -> 2 — Next | AS36: Aqua | AT36: Aqua
A37: G4 | B37: Animal health & welfare (incl. antimicrobial use) | C37: S | E37: GAP | F37: 0 | G37: 0 | H37: 0 | I37: 0 | J37: 0 | K37: 0 | L37: 0 | M37: 0 | N37: 0 | O37: 0 | P37: 0 | Q37: 0 | R37: 0 | S37: 2 | T37: 2 | U37: 2 | V37: 1 | W37: 0 | X37: 0 | Y37: 0 | Z37: 0 | AA37: 0 | AB37: 0 | AC37: 0 | AD37: 0 | AE37: 0 | AF37: 0 | AG37: 2 | AH37: 0 | AI37: 0 | AJ37: 0 | AL37: =SUMPRODUCT(F37:AJ37,$F$45:$AJ$45) -> 9 | AM37: =IF(SUMPRODUCT(--(F37:AJ37>0),--($F$45:$AJ$45=1),--($F$3:$AJ$3="Regulator"))>0,1,0) -> 0 | AN37: =IF(SUMPRODUCT(--(F37:AJ37>0),--($F$45:$AJ$45=1),--($F$3:$AJ$3="Customer"))>0,1,0) -> 1 | AO37: =IF(SUMPRODUCT(--(F37:AJ37>0),--($F$45:$AJ$45=1),--($F$3:$AJ$3="Investor"))>0,1,0) -> 0 | AP37: =IF(SUMPRODUCT(--(F37:AJ37>0),--($F$45:$AJ$45=1),--($F$3:$AJ$3="Industry / NGO"))>0,1,0) -> 1 | AQ37: =SUM(AM37:AP37) -> 2 | AR37: =IF(AND(OR(AS37="Wild",AS37="Aqua"),NOT(OR($C$51="both",$C$51=LOWER(AS37)))),"n/a — system",IF(AQ37=0,"—",IF(AND(AQ37>=$AR$2,AL37>=$AR$1),"1 — Build first",IF(AQ37>=3,"2 — Next","3 — Monitor")))) -> 3 — Monitor | AS37: Aqua | AT37: Aqua
B39: Column total (Σ scores) | F39: =SUM(F6:F37) -> 3 | G39: =SUM(G6:G37) -> 3 | H39: =SUM(H6:H37) -> 4 | I39: =SUM(I6:I37) -> 6 | J39: =SUM(J6:J37) -> 4 | K39: =SUM(K6:K37) -> 0 | L39: =SUM(L6:L37) -> 3 | M39: =SUM(M6:M37) -> 4 | ... AJ39: =SUM(AJ6:AJ37) -> 6 | AK39: =SUM(AR6:AR37) -> 0
B40: Topics touched (count ≥1) | F40: =COUNTIF(F6:F37,">0") -> 2 | G40: =COUNTIF(G6:G37,">0") -> 2 | H40: =COUNTIF(H6:H37,">0") -> 3 | I40: =COUNTIF(I6:I37,">0") -> 3 | J40: =COUNTIF(J6:J37,">0") -> 3 | K40: =COUNTIF(K6:K37,">0") -> 0 | L40: =COUNTIF(L6:L37,">0") -> 2 | M40: =COUNTIF(M6:M37,">0") -> 3 | ... AJ40: =COUNTIF(AJ6:AJ37,">0") -> 6 | AK40: =COUNTIF(AR6:AR37,">0") -> 0
B42: Framework system scope → | F42: Wild | G42: Wild | H42: Both | I42: Agnostic | J42: Agnostic | K42: Agnostic | L42: Agnostic | M42: Agnostic | N42: Agnostic | O42: Agnostic | P42: Agnostic | Q42: Agnostic | R42: Wild | S42: Aqua | T42: Aqua | U42: Aqua | V42: Both | W42: Agnostic | X42: Agnostic | Y42: Agnostic | Z42: Agnostic | AA42: Agnostic | AB42: Agnostic | AC42: Agnostic | AD42: Agnostic | AE42: Agnostic | AF42: Both | AG42: Both | AH42: Wild | AI42: Agnostic | AJ42: Agnostic
B44: Phase-3 scope status → | F44: SCORE | G44: SCORE | H44: SCORE | I44: SCORE | J44: SCORE | K44: SCORE | L44: SCORE | M44: SCORE | N44: SCORE | O44: OPT-IN (on; set 0 if N/A) [trigger: fluorinated HFC/HFO refrigerants] | P44: SCORE | Q44: OPT-IN (on; set 0 if N/A) [trigger: ≥150 employees] | R44: SCORE | S44: SCORE | T44: SCORE | U44: SCORE | V44: SCORE | W44: SCORE | X44: SCORE | Y44: SCORE | Z44: SCORE | AA44: SCORE | AB44: SCORE | AC44: SCORE | AD44: SCORE | AE44: SCORE | AF44: SCORE | AG44: SCORE | AH44: OPT-IN (off; set 1 if applies) [trigger: processes tuna] | AI44: SCORE | AJ44: SCORE
B45: Include switch (1/0) → | F45: =IF(OR(LOWER(F42)="agnostic",LOWER(F42)="both",$C$51="both",$C$51=LOWER(F42)),1,0) -> 1 | G45: =IF(OR(LOWER(G42)="agnostic",LOWER(G42)="both",$C$51="both",$C$51=LOWER(G42)),1,0) -> 1 | H45: =IF(OR(LOWER(H42)="agnostic",LOWER(H42)="both",$C$51="both",$C$51=LOWER(H42)),1,0) -> 1 | I45: =IF(OR(LOWER(I42)="agnostic",LOWER(I42)="both",$C$51="both",$C$51=LOWER(I42)),1,0) -> 1 | J45: =IF(OR(LOWER(J42)="agnostic",LOWER(J42)="both",$C$51="both",$C$51=LOWER(J42)),1,0) -> 1 | K45: =IF(OR(LOWER(K42)="agnostic",LOWER(K42)="both",$C$51="both",$C$51=LOWER(K42)),1,0) -> 1 | L45: =IF(OR(LOWER(L42)="agnostic",LOWER(L42)="both",$C$51="both",$C$51=LOWER(L42)),1,0) -> 1 | M45: =IF(OR(LOWER(M42)="agnostic",LOWER(M42)="both",$C$51="both",$C$51=LOWER(M42)),1,0) -> 1 | N45: =IF(OR(LOWER(N42)="agnostic",LOWER(N42)="both",$C$51="both",$C$51=LOWER(N42)),1,0) -> 1 | O45: =IF(LOWER($C$50)="yes",1,0) -> 1 | P45: =IF($C$48>=50,1,0) -> 1 | Q45: =IF($C$48>=150,1,0) -> 1 | R45: =IF(OR(LOWER(R42)="agnostic",LOWER(R42)="both",$C$51="both",$C$51=LOWER(R42)),1,0) -> 1 | S45: =IF(OR(LOWER(S42)="agnostic",LOWER(S42)="both",$C$51="both",$C$51=LOWER(S42)),1,0) -> 1 | T45: =IF(OR(LOWER(T42)="agnostic",LOWER(T42)="both",$C$51="both",$C$51=LOWER(T42)),1,0) -> 1 | U45: =IF(OR(LOWER(U42)="agnostic",LOWER(U42)="both",$C$51="both",$C$51=LOWER(U42)),1,0) -> 1 | V45: =IF(OR(LOWER(V42)="agnostic",LOWER(V42)="both",$C$51="both",$C$51=LOWER(V42)),1,0) -> 1 | W45: =IF(OR(LOWER(W42)="agnostic",LOWER(W42)="both",$C$51="both",$C$51=LOWER(W42)),1,0) -> 1 | X45: =IF(OR(LOWER(X42)="agnostic",LOWER(X42)="both",$C$51="both",$C$51=LOWER(X42)),1,0) -> 1 | Y45: =IF(OR(LOWER(Y42)="agnostic",LOWER(Y42)="both",$C$51="both",$C$51=LOWER(Y42)),1,0) -> 1 | ... AG45: =IF(OR(LOWER(AG42)="agnostic",LOWER(AG42)="both",$C$51="both",$C$51=LOWER(AG42)),1,0) -> 1 | AH45: =IF(AND(OR($C$51="both",$C$51=LOWER(AH42)),LOWER($C$49)="yes"),1,0) -> 0 | AI45: =IF(OR(LOWER(AI42)="agnostic",LOWER(AI42)="both",$C$51="both",$C$51=LOWER(AI42)),1,0) -> 1 | AJ45: =IF(OR(LOWER(AJ42)="agnostic",LOWER(AJ42)="both",$C$51="both",$C$51=LOWER(AJ42)),1,0) -> 1
A47: FIRM PROFILE — set these; the include-switches (row 46) update automatically
A48: Number of employees | C48: 150
A49: Processes tuna? (yes/no) | C49: no
A50: Operates own refrigeration using fluorinated (HFC/HFO) gases ≥5 t CO₂e (yes/no)? | C50: yes
B51: System (wild / aqua / both) | C51: both

Sheet Results
B1: SME PRIORITY VIEW — personalised hotspot ranking
B2: Firm profile: | C2: ='Coverage matrix'!C48 & " employees · tuna: " & 'Coverage matrix'!C49 & " · HFC refrigerant: " & 'Coverage matrix'!C50 & " · system: " & 'Coverage matrix'!C51 -> 150 employees · tuna: no · HFC refrigerant: yes · system: both
B3: Grouped by Stage, then ranked by convergence (cross-stakeholder consensus) and breadth (volume). Stage 1 = demanded across ≥3 stakeholder channels AND high volume (breadth ≥ 12) — the no-regret core to build first.
B5: # | C5: Topic | E5: Breadth | F5: Conv | G5: Reg | H5: Cust | I5: Inv | J5: NGO | K5: Stage | M5: sort idx
B6: 1 | C6: {=INDEX('Coverage matrix'!$B$6:$B$37,$M6)} -> Biodiversity & ecosystems (E4) | D6: {=IF(INDEX('Coverage matrix'!$D$6:$D$37,$M6)=0,"",INDEX('Coverage matrix'!$D$6:$D$37,$M6))} | E6: {=INDEX('Coverage matrix'!$AL$6:$AL$37,$M6)} -> 19 | F6: {=INDEX('Coverage matrix'!$AQ$6:$AQ$37,$M6)} -> 4 | G6: {=IF(INDEX('Coverage matrix'!$AM$6:$AM$37,$M6)=1,"✓","")} -> ✓ | H6: {=IF(INDEX('Coverage matrix'!$AN$6:$AN$37,$M6)=1,"✓","")} -> ✓ | I6: {=IF(INDEX('Coverage matrix'!$AO$6:$AO$37,$M6)=1,"✓","")} -> ✓ | J6: {=IF(INDEX('Coverage matrix'!$AP$6:$AP$37,$M6)=1,"✓","")} -> ✓ | K6: {=INDEX('Coverage matrix'!$AR$6:$AR$37,$M6)} -> 1 — Build first | M6: {=_xlfn.SORTBY(_xlfn.SEQUENCE(32),IF(LEFT('Coverage matrix'!$AR$6:$AR$37,1)="1",1,IF(LEFT('Coverage matrix'!$AR$6:$AR$37,1)="2",2,IF(LEFT('Coverage matrix'!$AR$6:$AR$37,1)="3",3,IF(LEFT('Coverage matrix'!$AR$6:$AR$37,1)="—",4,5)))),1,'Coverage matrix'!$AQ$6:$AQ$37,-1,'Coverage matrix'!$AL$6:$AL$37,-1)} -> 27
B7: 2 | C7: {=INDEX('Coverage matrix'!$B$6:$B$37,$M7)} -> E1-6 | D7: {=IF(INDEX('Coverage matrix'!$D$6:$D$37,$M7)=0,"",INDEX('Coverage matrix'!$D$6:$D$37,$M7))} -> Gross scopes 1, 2, 3 and total GHG emissions | E7: {=INDEX('Coverage matrix'!$AL$6:$AL$37,$M7)} -> 15 | F7: {=INDEX('Coverage matrix'!$AQ$6:$AQ$37,$M7)} -> 4 | G7: {=IF(INDEX('Coverage matrix'!$AM$6:$AM$37,$M7)=1,"✓","")} -> ✓ | H7: {=IF(INDEX('Coverage matrix'!$AN$6:$AN$37,$M7)=1,"✓","")} -> ✓ | I7: {=IF(INDEX('Coverage matrix'!$AO$6:$AO$37,$M7)=1,"✓","")} -> ✓ | J7: {=IF(INDEX('Coverage matrix'!$AP$6:$AP$37,$M7)=1,"✓","")} -> ✓ | K7: {=INDEX('Coverage matrix'!$AR$6:$AR$37,$M7)} -> 1 — Build first | M7: 4
B8: 3 | C8: {=INDEX('Coverage matrix'!$B$6:$B$37,$M8)} -> E5-5 | D8: {=IF(INDEX('Coverage matrix'!$D$6:$D$37,$M8)=0,"",INDEX('Coverage matrix'!$D$6:$D$37,$M8))} -> Resource outflows | E8: {=INDEX('Coverage matrix'!$AL$6:$AL$37,$M8)} -> 12 | F8: {=INDEX('Coverage matrix'!$AQ$6:$AQ$37,$M8)} -> 4 | G8: {=IF(INDEX('Coverage matrix'!$AM$6:$AM$37,$M8)=1,"✓","")} -> ✓ | H8: {=IF(INDEX('Coverage matrix'!$AN$6:$AN$37,$M8)=1,"✓","")} -> ✓ | I8: {=IF(INDEX('Coverage matrix'!$AO$6:$AO$37,$M8)=1,"✓","")} -> ✓ | J8: {=IF(INDEX('Coverage matrix'!$AP$6:$AP$37,$M8)=1,"✓","")} -> ✓ | K8: {=INDEX('Coverage matrix'!$AR$6:$AR$37,$M8)} -> 1 — Build first | M8: 11
B9: 4 | C9: {=INDEX('Coverage matrix'!$B$6:$B$37,$M9)} -> Wild-stock status / sustainable wild sourcing | D9: {=IF(INDEX('Coverage matrix'!$D$6:$D$37,$M9)=0,"",INDEX('Coverage matrix'!$D$6:$D$37,$M9))} | E9: {=INDEX('Coverage matrix'!$AL$6:$AL$37,$M9)} -> 12 | F9: {=INDEX('Coverage matrix'!$AQ$6:$AQ$37,$M9)} -> 4 | G9: {=IF(INDEX('Coverage matrix'!$AM$6:$AM$37,$M9)=1,"✓","")} -> ✓ | H9: {=IF(INDEX('Coverage matrix'!$AN$6:$AN$37,$M9)=1,"✓","")} -> ✓ | I9: {=IF(INDEX('Coverage matrix'!$AO$6:$AO$37,$M9)=1,"✓","")} -> ✓ | J9: {=IF(INDEX('Coverage matrix'!$AP$6:$AP$37,$M9)=1,"✓","")} -> ✓ | K9: {=INDEX('Coverage matrix'!$AR$6:$AR$37,$M9)} -> 1 — Build first | M9: 30
B10: 5 | C10: {=INDEX('Coverage matrix'!$B$6:$B$37,$M10)} -> Supply-chain traceability (chain of custody) | D10: {=IF(INDEX('Coverage matrix'!$D$6:$D$37,$M10)=0,"",INDEX('Coverage matrix'!$D$6:$D$37,$M10))} | E10: {=INDEX('Coverage matrix'!$AL$6:$AL$37,$M10)} -> 22 | F10: {=INDEX('Coverage matrix'!$AQ$6:$AQ$37,$M10)} -> 3 | G10: {=IF(INDEX('Coverage matrix'!$AM$6:$AM$37,$M10)=1,"✓","")} -> ✓ | H10: {=IF(INDEX('Coverage matrix'!$AN$6:$AN$37,$M10)=1,"✓","")} -> ✓ | I10: {=IF(INDEX('Coverage matrix'!$AO$6:$AO$37,$M10)=1,"✓","")} | J10: {=IF(INDEX('Coverage matrix'!$AP$6:$AP$37,$M10)=1,"✓","")} -> ✓ | K10: {=INDEX('Coverage matrix'!$AR$6:$AR$37,$M10)} -> 1 — Build first | M10: 29
B11: 6 | C11: {=INDEX('Coverage matrix'!$B$6:$B$37,$M11)} -> E3-4 | D11: {=IF(INDEX('Coverage matrix'!$D$6:$D$37,$M11)=0,"",INDEX('Coverage matrix'!$D$6:$D$37,$M11))} -> Water consumption | E11: {=INDEX('Coverage matrix'!$AL$6:$AL$37,$M11)} -> 16 | F11: {=INDEX('Coverage matrix'!$AQ$6:$AQ$37,$M11)} -> 3 | G11: {=IF(INDEX('Coverage matrix'!$AM$6:$AM$37,$M11)=1,"✓","")} | H11: {=IF(INDEX('Coverage matrix'!$AN$6:$AN$37,$M11)=1,"✓","")} -> ✓ | I11: {=IF(INDEX('Coverage matrix'!$AO$6:$AO$37,$M11)=1,"✓","")} -> ✓ | J11: {=IF(INDEX('Coverage matrix'!$AP$6:$AP$37,$M11)=1,"✓","")} -> ✓ | K11: {=INDEX('Coverage matrix'!$AR$6:$AR$37,$M11)} -> 1 — Build first | M11: 8
B12: 7 | C12: {=INDEX('Coverage matrix'!$B$6:$B$37,$M12)} -> S2-1 | D12: {=IF(INDEX('Coverage matrix'!$D$6:$D$37,$M12)=0,"",INDEX('Coverage matrix'!$D$6:$D$37,$M12))} -> Policies related to value chain workers | E12: {=INDEX('Coverage matrix'!$AL$6:$AL$37,$M12)} -> 15 | F12: {=INDEX('Coverage matrix'!$AQ$6:$AQ$37,$M12)} -> 3 | G12: {=IF(INDEX('Coverage matrix'!$AM$6:$AM$37,$M12)=1,"✓","")} -> ✓ | H12: {=IF(INDEX('Coverage matrix'!$AN$6:$AN$37,$M12)=1,"✓","")} -> ✓ | I12: {=IF(INDEX('Coverage matrix'!$AO$6:$AO$37,$M12)=1,"✓","")} | J12: {=IF(INDEX('Coverage matrix'!$AP$6:$AP$37,$M12)=1,"✓","")} -> ✓ | K12: {=INDEX('Coverage matrix'!$AR$6:$AR$37,$M12)} -> 1 — Build first | M12: 24
B13: 8 | C13: {=INDEX('Coverage matrix'!$B$6:$B$37,$M13)} -> E1-5 | D13: {=IF(INDEX('Coverage matrix'!$D$6:$D$37,$M13)=0,"",INDEX('Coverage matrix'!$D$6:$D$37,$M13))} -> Energy consumption and mix | E13: {=INDEX('Coverage matrix'!$AL$6:$AL$37,$M13)} -> 12 | F13: {=INDEX('Coverage matrix'!$AQ$6:$AQ$37,$M13)} -> 3 | G13: {=IF(INDEX('Coverage matrix'!$AM$6:$AM$37,$M13)=1,"✓","")} | H13: {=IF(INDEX('Coverage matrix'!$AN$6:$AN$37,$M13)=1,"✓","")} -> ✓ | I13: {=IF(INDEX('Coverage matrix'!$AO$6:$AO$37,$M13)=1,"✓","")} -> ✓ | J13: {=IF(INDEX('Coverage matrix'!$AP$6:$AP$37,$M13)=1,"✓","")} -> ✓ | K13: {=INDEX('Coverage matrix'!$AR$6:$AR$37,$M13)} -> 1 — Build first | M13: 3
B14: 9 | C14: {=INDEX('Coverage matrix'!$B$6:$B$37,$M14)} -> S1-14 | D14: {=IF(INDEX('Coverage matrix'!$D$6:$D$37,$M14)=0,"",INDEX('Coverage matrix'!$D$6:$D$37,$M14))} -> Health and safety metrics | E14: {=INDEX('Coverage matrix'!$AL$6:$AL$37,$M14)} -> 12 | F14: {=INDEX('Coverage matrix'!$AQ$6:$AQ$37,$M14)} -> 3 | G14: {=IF(INDEX('Coverage matrix'!$AM$6:$AM$37,$M14)=1,"✓","")} -> ✓ | H14: {=IF(INDEX('Coverage matrix'!$AN$6:$AN$37,$M14)=1,"✓","")} -> ✓ | I14: {=IF(INDEX('Coverage matrix'!$AO$6:$AO$37,$M14)=1,"✓","")} | J14: {=IF(INDEX('Coverage matrix'!$AP$6:$AP$37,$M14)=1,"✓","")} -> ✓ | K14: {=INDEX('Coverage matrix'!$AR$6:$AR$37,$M14)} -> 1 — Build first | M14: 17
B15: 10 | C15: {=INDEX('Coverage matrix'!$B$6:$B$37,$M15)} -> S1-17 | D15: {=IF(INDEX('Coverage matrix'!$D$6:$D$37,$M15)=0,"",INDEX('Coverage matrix'!$D$6:$D$37,$M15))} -> Incidents, complaints and severe human rights impacts | E15: {=INDEX('Coverage matrix'!$AL$6:$AL$37,$M15)} -> 11 | F15: {=INDEX('Coverage matrix'!$AQ$6:$AQ$37,$M15)} -> 4 | G15: {=IF(INDEX('Coverage matrix'!$AM$6:$AM$37,$M15)=1,"✓","")} -> ✓ | H15: {=IF(INDEX('Coverage matrix'!$AN$6:$AN$37,$M15)=1,"✓","")} -> ✓ | I15: {=IF(INDEX('Coverage matrix'!$AO$6:$AO$37,$M15)=1,"✓","")} -> ✓ | J15: {=IF(INDEX('Coverage matrix'!$AP$6:$AP$37,$M15)=1,"✓","")} -> ✓ | K15: {=INDEX('Coverage matrix'!$AR$6:$AR$37,$M15)} -> 2 — Next | M15: 18
B16: 11 | C16: {=INDEX('Coverage matrix'!$B$6:$B$37,$M16)} -> G1-1 | D16: {=IF(INDEX('Coverage matrix'!$D$6:$D$37,$M16)=0,"",INDEX('Coverage matrix'!$D$6:$D$37,$M16))} -> Corporate culture and business conduct policies and corporate culture | E16: {=INDEX('Coverage matrix'!$AL$6:$AL$37,$M16)} -> 9 | F16: {=INDEX('Coverage matrix'!$AQ$6:$AQ$37,$M16)} -> 4 | G16: {=IF(INDEX('Coverage matrix'!$AM$6:$AM$37,$M16)=1,"✓","")} -> ✓ | H16: {=IF(INDEX('Coverage matrix'!$AN$6:$AN$37,$M16)=1,"✓","")} -> ✓ | I16: {=IF(INDEX('Coverage matrix'!$AO$6:$AO$37,$M16)=1,"✓","")} -> ✓ | J16: {=IF(INDEX('Coverage matrix'!$AP$6:$AP$37,$M16)=1,"✓","")} -> ✓ | K16: {=INDEX('Coverage matrix'!$AR$6:$AR$37,$M16)} -> 2 — Next | M16: 12
B17: 12 | C17: {=INDEX('Coverage matrix'!$B$6:$B$37,$M17)} -> E1-3 | D17: {=IF(INDEX('Coverage matrix'!$D$6:$D$37,$M17)=0,"",INDEX('Coverage matrix'!$D$6:$D$37,$M17))} -> Actions and resources in relation to climate change policies | E17: {=INDEX('Coverage matrix'!$AL$6:$AL$37,$M17)} -> 7 | F17: {=INDEX('Coverage matrix'!$AQ$6:$AQ$37,$M17)} -> 4 | G17: {=IF(INDEX('Coverage matrix'!$AM$6:$AM$37,$M17)=1,"✓","")} -> ✓ | H17: {=IF(INDEX('Coverage matrix'!$AN$6:$AN$37,$M17)=1,"✓","")} -> ✓ | I17: {=IF(INDEX('Coverage matrix'!$AO$6:$AO$37,$M17)=1,"✓","")} -> ✓ | J17: {=IF(INDEX('Coverage matrix'!$AP$6:$AP$37,$M17)=1,"✓","")} -> ✓ | K17: {=INDEX('Coverage matrix'!$AR$6:$AR$37,$M17)} -> 2 — Next | M17: 1
B18: 13 | C18: {=INDEX('Coverage matrix'!$B$6:$B$37,$M18)} -> Feed & marine ingredients sourcing | D18: {=IF(INDEX('Coverage matrix'!$D$6:$D$37,$M18)=0,"",INDEX('Coverage matrix'!$D$6:$D$37,$M18))} | E18: {=INDEX('Coverage matrix'!$AL$6:$AL$37,$M18)} -> 10 | F18: {=INDEX('Coverage matrix'!$AQ$6:$AQ$37,$M18)} -> 3 | G18: {=IF(INDEX('Coverage matrix'!$AM$6:$AM$37,$M18)=1,"✓","")} -> ✓ | H18: {=IF(INDEX('Coverage matrix'!$AN$6:$AN$37,$M18)=1,"✓","")} -> ✓ | I18: {=IF(INDEX('Coverage matrix'!$AO$6:$AO$37,$M18)=1,"✓","")} | J18: {=IF(INDEX('Coverage matrix'!$AP$6:$AP$37,$M18)=1,"✓","")} -> ✓ | K18: {=INDEX('Coverage matrix'!$AR$6:$AR$37,$M18)} -> 2 — Next | M18: 31
... B37: 32 | C37: {=INDEX('Coverage matrix'!$B$6:$B$37,$M37)} -> E3-2 | D37: {=IF(INDEX('Coverage matrix'!$D$6:$D$37,$M37)=0,"",INDEX('Coverage matrix'!$D$6:$D$37,$M37))} -> Actions and resources related to water and marine resources | E37: {=INDEX('Coverage matrix'!$AL$6:$AL$37,$M37)} -> 1 | F37: {=INDEX('Coverage matrix'!$AQ$6:$AQ$37,$M37)} -> 1 | G37: {=IF(INDEX('Coverage matrix'!$AM$6:$AM$37,$M37)=1,"✓","")} | H37: {=IF(INDEX('Coverage matrix'!$AN$6:$AN$37,$M37)=1,"✓","")} -> ✓ | I37: {=IF(INDEX('Coverage matrix'!$AO$6:$AO$37,$M37)=1,"✓","")} | J37: {=IF(INDEX('Coverage matrix'!$AP$6:$AP$37,$M37)=1,"✓","")} | K37: {=INDEX('Coverage matrix'!$AR$6:$AR$37,$M37)} -> 3 — Monitor | M37: 6

Sheet Justifications log
A1: Topic / DR | B1: ESRS id | C1: Framework | D1: Score (1/2) | E1: Clause / indicator ref | F1: One-line justification | G1: Source (doc, date, page/URL) | T1: E1-3 | V1: Fisheries Control Regulation (2023/2842)
A2: Policies related to water and marine resources | B2: E3-1 | C2: CSDDD (2024/1760) | D2: 1 | E2: Annex Pt I(15); Art 7 | F2: Water/air pollution & excessive water consumption are listed adverse environmental impacts, but only where they harm people/ecosystems; CSDDD mandates a generic DD policy, not a water-specific disclosure. | G2: Directive (EU) 2024/1760, consolidated 18.03.2026 — EUR-Lex CELEX:02024L1760-20260318 | T2: E1-5 | V2: CMO marketing standards (1379/2013)
A3: Actions and resources related to water and marine resources | B3: E3-2 | C3: CSDDD (2024/1760) | D3: 1 | E3: Annex Pt I(15); Art 10–11 | F3: Mitigating water/marine impacts falls under the prevent / bring-to-an-end duties as a process obligation, not as this specific action DR. | G3: Directive (EU) 2024/1760, consolidated 18.03.2026 — EUR-Lex CELEX:02024L1760-20260318 | T3: E1-6 | V3: PPWR (2025/40)
A4: Targets related to water and marine resources | B4: E3-3 | C4: CSDDD (2024/1760) | D4: 1 | E4: Annex Pt I(15); Art 10(2)(a) | F4: Prevention/corrective action plans must carry time-bound qualitative & quantitative indicators, but CSDDD sets no water-target disclosure. | G4: Directive (EU) 2024/1760, consolidated 18.03.2026 — EUR-Lex CELEX:02024L1760-20260318 | T4: E3-1 | V4: OSH Framework Directive (89/391/EEC)
A5: Water consumption | B5: E3-4 | C5: CSDDD (2024/1760) | D5: 1 | E5: Annex Pt I(15) | F5: 'Excessive water consumption' is expressly named as environmental degradation — the strongest E3 hook — but framed as impact-on-people, not a consumption metric. | G5: Directive (EU) 2024/1760, consolidated 18.03.2026 — EUR-Lex CELEX:02024L1760-20260318 | T5: E3-2 | V5: Working Time Directive (2003/88/EC)
A6: Corporate culture and business conduct policies and corporate culture | B6: G1-1 | C6: CSDDD (2024/1760) | D6: 1 | E6: Art 7(2)(b) | F6: CSDDD requires a code of conduct within the DD policy — partial overlap with business-conduct culture; broader corporate culture not covered. | G6: Directive (EU) 2024/1760, consolidated 18.03.2026 — EUR-Lex CELEX:02024L1760-20260318 | T6: E3-4 | V6: EUDR (2023/1115)
A7: Policies related to own workforce | B7: S1-1 | C7: CSDDD (2024/1760) | D7: 2 | E7: Art 7(1)–(2) | F7: Mandatory DD policy plus a code of conduct, developed in consultation with employees, addressing impacts on the own workforce. | G7: Directive (EU) 2024/1760, consolidated 18.03.2026 — EUR-Lex CELEX:02024L1760-20260318 | T7: E5-2 | V7: EmpCo Directive (2024/825)
A8: Health and safety metrics | B8: S1-14 | C8: CSDDD (2024/1760) | D8: 1 | E8: Annex Pt I(6) | F8: 'Safe and healthy working conditions' is a listed adverse impact, so OSH due diligence is required; the H&S coverage metric itself is not. | G8: Directive (EU) 2024/1760, consolidated 18.03.2026 — EUR-Lex CELEX:02024L1760-20260318 | T8: E5-4 | V8: Fisheries labour conditions (2017/159)
A9: Incidents, complaints and severe human rights impacts | B9: S1-17 | C9: CSDDD (2024/1760) | D9: 1 | E9: Art 14; Annex Pt I(9)–(12); Art 3(l) | F9: CSDDD mandates a complaints mechanism and due diligence on severe human-rights impacts (forced/child labour), but not the incident-count disclosure. | G9: Directive (EU) 2024/1760, consolidated 18.03.2026 — EUR-Lex CELEX:02024L1760-20260318 | T9: E5-5 | V9: MSC
A10: Processes for engaging with own workers and workers’ representatives about impacts | B10: S1-2 | C10: CSDDD (2024/1760) | D10: 2 | E10: Art 13(1),(3); Art 7(2) | F10: Meaningful stakeholder engagement expressly includes the company's own employees and their representatives. | G10: Directive (EU) 2024/1760, consolidated 18.03.2026 — EUR-Lex CELEX:02024L1760-20260318 | T10: G1-1 | V10: ASC
A11: Processes to remediate negative impacts and channels for own workers to raise concerns | B11: S1-3 | C11: CSDDD (2024/1760) | D11: 2 | E11: Art 12; Art 14 | F11: Remediation duty plus a mandatory notification/complaints procedure for own workers to raise concerns. | G11: Directive (EU) 2024/1760, consolidated 18.03.2026 — EUR-Lex CELEX:02024L1760-20260318 | T11: G1-3 | V11: Best Aquaculture Practices (BAP)
A12: Taking action on material impacts on own workforce, and approaches to mitigating material risks and pursuing material opportunities related to own workforce, and effectiveness of those action | B12: S1-4 | C12: CSDDD (2024/1760) | D12: 2 | E12: Art 10; Art 11 | F12: Core prevent / bring-to-an-end duties applied to actual and potential adverse impacts on the own workforce. | G12: Directive (EU) 2024/1760, consolidated 18.03.2026 — EUR-Lex CELEX:02024L1760-20260318 | T12: G1-4 | V12: GLOBALG.A.P. Aquaculture
A13: Policies related to value chain workers | B13: S2-1 | C13: CSDDD (2024/1760) | D13: 2 | E13: Art 7(2)(b); Annex Pt I(6)–(14) | F13: Code of conduct extended to business partners across the chain of activities, covering value-chain workers' human rights — the heart of CSDDD. | G13: Directive (EU) 2024/1760, consolidated 18.03.2026 — EUR-Lex CELEX:02024L1760-20260318 | T13: G1-5 | V13: Friend of the Sea
... A24: Supply-chain traceability (chain of custody) | B24: — | C24: CMO marketing standards (1379/2013) | D24: 2 | E24: Art 35 (label data flow) | F24: The mandatory label data (area, gear, method) must accompany the product, requiring upstream information flow — touches traceability though the traceability system itself sits in the Control/IUU regimes. | G24: Reg (EU) No 1379/2013 — EUR-Lex: Regulation (EU) No 1379/2013 | T24: Biodiversity & ecosystems (E4) | V24: FIPs / FisheryProgress
A25: Consumers & end-users (s4) | B25: S4 | C25: CMO marketing standards (1379/2013) | D25: 1 | E25: Art 35 (mandatory consumer information) → S4 "information-related impacts for consumers" sub-topic | F25: CMO mandates consumer product information (species, production method, catch area); bears on the S4 consumer-information sub-topic but demands no specific S4 datapoint → touched, not required | G25: Regulation (EU) 1379/2013, Art 35
A26: Wild-stock status / sustainable wild sourcing | B26: — | C26: CMO marketing standards (1379/2013) | D26: 1 | E26: Art 35(1) catch-area/gear labelling [v] | F26: Compulsory catch-area and gear-category labelling makes wild sourcing partially transparent to buyers and consumers — adjacent to sustainable-sourcing disclosure. | G26: Reg (EU) No 1379/2013 — EUR-Lex: Regulation (EU) No 1379/2013 | T26: Consumer health & food safety (S4) | V26: GDST
A27: Actions and resources related to resource use and circular economy | B27: E5-2 | C27: PPWR (2025/40) | D27: 2 | E27: recyclability + recycled-content + reuse arts | F27: Directly mandates circular-economy actions on packaging — recyclability design, recycled-content minima, reuse/refill and waste-reduction obligations. | G27: Reg (EU) 2025/40 (PPWR) — EUR-Lex: Regulation (EU) 2025/40 | T27: Supply-chain traceability (chain of custody) | V27: GSSI
A28: Resource inflows | B28: E5-4 | C28: PPWR (2025/40) | D28: 2 | E28: recycled-content art [v] | F28: Minimum recycled-content requirements bear on material inflows (recyclate as input), but PPWR frames them as packaging design rather than an inflow-accounting duty. | G28: Reg (EU) 2025/40 (PPWR) — EUR-Lex: : Regulation (EU) 2025/40 | T28: Wild-stock status / sustainable wild sourcing | V28: GRI Standards (incl. GRI 13)
A29: Resource outflows | B29: E5-5 | C29: PPWR (2025/40) | D29: 2 | E29: waste-reduction / reuse-target arts [v] | F29: Packaging-waste minimisation, recyclability and reuse targets directly govern resource outflows and packaging waste. | G29: Reg (EU) 2025/40 (PPWR) — EUR-Lex: : Regulation (EU) 2025/40 | T29: Feed & marine ingredients sourcing | V29: ISSF
A30: Health and safety metrics | B30: S1-14 | C30: OSH Framework Directive (89/391/EEC) | D30: 2 | E30: Art 6 general obligations; Art 9 accident records | F30: Core employer duty to ensure workers’ safety and health via risk assessment and preventive measures, plus the duty to keep a list of and report occupational accidents — the substantive H&S obligation underlying the S1 H&S topic. | G30: Council Dir 89/391/EEC — EUR-Lex:Council Directive 89/391/EEC | T30: Antimicrobial use (AMU) | V30: SeaBOS
A31: Policies related to own workforce (S1-1) | B31: S1-1 | C31: OSH Framework Directive (89/391/EEC) | D31: 2 | E31: Arts 6 & 9 → S1-1_09 (accident-prevention policy/mgmt system), S1-1_18 (H&S environment) | F31: OSH mandates a workplace accident-prevention policy/management system and risk assessment — direct hit on S1-1_09/18Directive 89/391/EEC, Arts 6 & 9 | G31: Council Dir 89/391/EEC — EUR-Lex: Council Directive 89/391/EEC
A32: Processes for engaging with own workers and workers’ representatives about impacts | B32: S1-2 | C32: OSH Framework Directive (89/391/EEC) | D32: 1 | E32: Art 10–11 information & consultation | F32: Mandates information, consultation and participation of workers and their representatives — worker engagement, but scoped to health & safety matters. | G32: Council Dir 89/391/EEC — EUR-Lex: Council Directive 89/391/EEC | T32: Animal welfare | V32: SBTi
A33: Taking action on material impacts on own workforce, and approaches to mitigating material risks and pursuing material opportunities related to own workforce, and effectiveness of those action | B33: S1-4 | C33: OSH Framework Directive (89/391/EEC) | D33: 1 | E33: Art 6 preventive/protective measures | F33: Requires preventive and protective measures to act on workplace risks — action on a material own-workforce (H&S) impact. | G33: Council Dir 89/391/EEC — EUR-Lex: Council Directive 89/391/EEC | V33: UN SDGs
A34: Taking action on material impacts on own workforce, and approaches to mitigating material risks and pursuing material opportunities related to own workforce, and effectiveness of those action | B34: S1-4 | C34: Working Time Directive (2003/88/EC) | D34: 0 | E34: — (out of frame) | F34: REVISED 1->0: working-time standards map natively to S1-11/S1-15 (out of universe); S1-4 datapoints are narrative actions-on-impacts, not a working-time standard. Recorded in out-of-frame register, not coded. | G34: Dir 2003/88/EC — EUR-Lex | V34: Move to Minus 15
A35: Incidents, complaints and severe human rights impacts | B35: S1-17 | C35: Forced Labour Regulation (2024/3015) | D35: 1 | E35: Art 3 prohibition | F35: Prohibits placing on / making available products made with forced labour — forced labour is the archetypal severe human-rights impact (own and value-chain workers), but FLR is a market ban, not an incident-disclosure duty. | G35: Reg (EU) 2024/3015 (Forced Labour Regulation) — EUR-Lex: Regulation (EU) 2024/3015 | V35: CSRD / ESRS [BASELINE — excluded from sums]
A36: Policies related to value chain workers | B36: S2-1 | C36: Forced Labour Regulation (2024/3015) | D36: 2 | E36: Art 3 (market prohibition) → S2-1_05 (forced labour) | F36: Targets forced labour anywhere in the supply chain, bearing on value-chain worker protection — coded as a product market-ban rather than a policy/engagement requirement. [FLAG: arguably 2 since it explicitly addresses the topic.] | G36: Reg (EU) 2024/3015 (Forced Labour Regulation) — EUR-Lex: Regulation (EU) 2024/3015
A37: Biodiversity & ecosystems (E4) | B37: Biodiversity & ecosystems (E4) | C37: EUDR (2023/1115) | D37: 2 | E37: Arts 3 & 8 (deforestation-free + due diligence) → E4-2_20 (deforestation policy), E4-5_05 (land conversion) | F37: Purpose is to curb deforestation and forest degradation in commodity supply chains — addresses ecosystem/biodiversity loss relevant to E4 where the processor handles in-scope commodities. | G37: Reg (EU) 2023/1115 (EUDR) — EUR-Lex
A38: Supply-chain traceability (chain of custody) | B38: — | C38: EUDR (2023/1115) | D38: 1 | E38: Art 9 geolocation; Art 4 DD statement [v] | F38: Requires plot-level geolocation and due-diligence statements traceable to origin for in-scope commodities — a strong traceability duty, but for deforestation commodities (e.g. soy/palm in feed), not seafood chain of custody. | G38: Reg (EU) 2023/1115 (EUDR) — EUR-Lex
A39: Feed & marine ingredients sourcing | B39: — | C39: EUDR (2023/1115) | D39: 1 | E39: Annex I + Art 3 DD obligation [v] | F39: Soy/palm in aquafeed are in-scope EUDR commodities, so the deforestation-commodity slice of feed carries a due-diligence duty. [FLAG applicability: for a processor buying finished feed, the EUDR duty may sit with the feed supplier — consider context/indirect or 0.] | G39: Reg (EU) 2023/1115 (EUDR) — EUR-Lex
A40: Consumers & end-users (s4) | B40: S4 | C40: EmpCo Directive (2024/825) | D40: 1 | E40: amends UCPD 2005/29/EC Arts 6–7 | F40: Bans generic/unsubstantiated environmental claims and regulates sustainability labels in B2C commercial practices — a consumer-protection duty touching the S4 consumer topic, but governing how claims are made rather than any sustainability performance or disclosure. [FLAG: weak fit; reviewer may treat EmpCo as context (0).] | G40: Dir (EU) 2024/825 (EmpCo) amending Dir 2005/29/EC — EUR-Lex: Regulation (EU) No 2024/825
A41: Actions and resources in relation to climate change policies | B41: E1-3 | C41: F-gas Regulation (2024/573) | D41: 1 | E41: leak-check / containment / recovery arts | F41: Mandatory HFC phase-down, leak checks, containment and recovery for refrigeration operators is a binding climate-mitigation action on the refrigerant slice of operations. (Conditional: profile = uses HFC/HFO.) | G41: Reg (EU) 2024/573 (F-gas) — EUR-Lex
A42: Gross scopes 1, 2, 3 and total GHG emissions | B42: E1-6 | C42: F-gas Regulation (2024/573) | D42: 1 | E42: Arts 4–6, 26 → E1-6_07 (Gross Scope 1 GHG) | F42: Binding leak-control/recovery + reporting of fluorinated-gas (Scope-1) emissions addresses the Scope-1 GHG datapoint substance | G42: Reg (EU) 2024/573 (F-gas) — EUR-Lex
A43: Processes to remediate negative impacts and channels for own workers to raise concerns | B43: S1-3 | C43: Whistleblowing Directive (2019/1937) | D43: 2 | E43: Art 8 internal channels; Art 4 personal scope | F43: Requires legal entities with ≥50 workers to establish internal reporting channels and protect reporting persons — a direct, mandated channel for workers to raise concerns. | G43: Dir (EU) 2019/1937 (Whistleblowing) — EUR-Lex
A44: Corporate culture and business conduct policies and corporate culture | B44: G1-1 | C44: Whistleblowing Directive (2019/1937) | D44: 2 | E44: Arts 8–9 → G1-1_05/06 (reporting safeguards, whistle-blower protection) | F44: Datapoint check: G1-1 carries dedicated whistleblowing datapoints (G1-1_05 safeguards for reporting irregularities incl. whistleblowing; G1-1_06 whistle-blower protection policy; G1-1_12 entity subject to whistleblower legal requirements). The Directive maps to these explicitly -> upgraded 1->2. | G44: Dir (EU) 2019/1937 (Whistleblowing) — EUR-Lex
A45: Prevention and detection of corruption and bribery | B45: G1-3 | C45: Whistleblowing Directive (2019/1937) | D45: 0 | E45: — (removed on datapoint check) | F45: REMOVED 1->0: G1-3 datapoints are anti-corruption procedures/training only; whistleblowing maps to G1-1 (above), not G1-3. Dropped to avoid double-counting the same instrument across two governance rows. | G45: Dir (EU) 2019/1937 (Whistleblowing) — EUR-Lex
