Workbook

Sheet INSTRUCTIONS
A1: Workbook purpose | B1: workbook mapping sustainability report disclosures from 6 companies onto topical ESRS datapoints, quantify cross-company reporting overlap, and generate a shortlist for later scoring on ease of reporting and usefulness
A2: Important methodological note | B2: This workbook measures reported ESRS-aligned coverage in practice (from Sustainability Reports) - It does NOT prove formal legal ESRS compliance
A3: Suggested company set | B3: Bolton; Espersen; Mowi; Nomad Foods; Profand; Thai Union

Sheet ESRS_MASTER
A1: Source: ESRS_EFRAG_EXCELL | B1: https://viewpoint.pwc.com/dt/us/en/esrs/esrs/esrs/efrag-ig/efrag-ig3.html
A3: ESRS_ID | B3: ESRS_LAYER | C3: Topic | D3: Subtopic | E3: DR | F3: Paragraph | G3: Related_AR | H3: Official_Datapoint_Name | I3: Data_Type | J3: Conditional_or_Alternative_DP | K3: May_Voluntary | L3: Appendix_B_Linkage | M3: Phasing_LT_750 | N3: Phasing_All | O3: Quant_or_Qual | P3: Processing_Relevance_Default | Q3: Priority_Screen | R3: Keyword_1 | S3: Keyword_2 | T3: Keyword_3
A4: E1.GOV-3_01 | B4: =IF(ISNUMBER(SEARCH(".IRO",A4)),"Exclude", IF(ISNUMBER(SEARCH(".GOV",A4)),"Exclude", IF(ISNUMBER(SEARCH(".SBM",A4)),"Exclude", IF(ISNUMBER(SEARCH(".MDR",A4)),"Exclude", "Keep")))) -> Exclude | C4: E1 | E4: E1.GOV-3 | F4: 13 | H4: Disclosure of whether and how climate-related considerations are factored into remuneration of members of administrative, management and supervisory bodies | I4: narrative | O4: Qualitative | Q4: In scope
A5: E1.GOV-3_02 | B5: =IF(ISNUMBER(SEARCH(".IRO",A5)),"Exclude", IF(ISNUMBER(SEARCH(".GOV",A5)),"Exclude", IF(ISNUMBER(SEARCH(".SBM",A5)),"Exclude", IF(ISNUMBER(SEARCH(".MDR",A5)),"Exclude", "Keep")))) -> Exclude | C5: E1 | E5: E1.GOV-3 | F5: 13 | H5: Percentage of remuneration recognised that is linked to climate related considerations | I5: percent | O5: Quantitative | Q5: In scope
A6: E1.GOV-3_03 | B6: =IF(ISNUMBER(SEARCH(".IRO",A6)),"Exclude", IF(ISNUMBER(SEARCH(".GOV",A6)),"Exclude", IF(ISNUMBER(SEARCH(".SBM",A6)),"Exclude", IF(ISNUMBER(SEARCH(".MDR",A6)),"Exclude", "Keep")))) -> Exclude | C6: E1 | E6: E1.GOV-3 | F6: 13 | H6: Explanation of climate-related considerations that are factored into remuneration of members of administrative, management and supervisory bodies | I6: narrative | O6: Qualitative | Q6: In scope
A7: E1-1_01 | B7: =IF(ISNUMBER(SEARCH(".IRO",A7)),"Exclude", IF(ISNUMBER(SEARCH(".GOV",A7)),"Exclude", IF(ISNUMBER(SEARCH(".SBM",A7)),"Exclude", IF(ISNUMBER(SEARCH(".MDR",A7)),"Exclude", "Keep")))) -> Keep | C7: E1 | E7: E1-1 | F7: 14 | G7: AR 1 | H7: Disclosure of transition plan for climate change mitigation | I7: narrative | L7: CL | O7: Qualitative | Q7: In scope
A8: E1-1_02 | B8: =IF(ISNUMBER(SEARCH(".IRO",A8)),"Exclude", IF(ISNUMBER(SEARCH(".GOV",A8)),"Exclude", IF(ISNUMBER(SEARCH(".SBM",A8)),"Exclude", IF(ISNUMBER(SEARCH(".MDR",A8)),"Exclude", "Keep")))) -> Keep | C8: E1 | E8: E1-1 | F8: 16 a | G8: AR 2 | H8: Explanation of how targets are compatible with limiting of global warming to one and half degrees Celsius in line with Paris Agreement | I8: narrative | O8: Qualitative | Q8: In scope
A9: E1-1_03 | B9: =IF(ISNUMBER(SEARCH(".IRO",A9)),"Exclude", IF(ISNUMBER(SEARCH(".GOV",A9)),"Exclude", IF(ISNUMBER(SEARCH(".SBM",A9)),"Exclude", IF(ISNUMBER(SEARCH(".MDR",A9)),"Exclude", "Keep")))) -> Keep | C9: E1 | E9: E1-1 | F9: 16 b | H9: Disclosure of decarbonisation levers and key action | I9: narrative | O9: Qualitative | Q9: In scope
A10: E1-1_04 | B10: =IF(ISNUMBER(SEARCH(".IRO",A10)),"Exclude", IF(ISNUMBER(SEARCH(".GOV",A10)),"Exclude", IF(ISNUMBER(SEARCH(".SBM",A10)),"Exclude", IF(ISNUMBER(SEARCH(".MDR",A10)),"Exclude", "Keep")))) -> Keep | C10: E1 | E10: E1-1 | F10: 16 c | H10: Disclosure of significant operational expenditures (Opex) and (or) capital expenditures (Capex) required for implementation of action plan | I10: narrative | O10: Qualitative | Q10: In scope
A11: E1-1_05 | B11: =IF(ISNUMBER(SEARCH(".IRO",A11)),"Exclude", IF(ISNUMBER(SEARCH(".GOV",A11)),"Exclude", IF(ISNUMBER(SEARCH(".SBM",A11)),"Exclude", IF(ISNUMBER(SEARCH(".MDR",A11)),"Exclude", "Keep")))) -> Keep | C11: E1 | E11: E1-1 | F11: 16 c | H11: Financial resources allocated to action plan (OpEx) | I11: monetary | O11: Quantitative | Q11: In scope
A12: E1-1_06 | B12: =IF(ISNUMBER(SEARCH(".IRO",A12)),"Exclude", IF(ISNUMBER(SEARCH(".GOV",A12)),"Exclude", IF(ISNUMBER(SEARCH(".SBM",A12)),"Exclude", IF(ISNUMBER(SEARCH(".MDR",A12)),"Exclude", "Keep")))) -> Keep | C12: E1 | E12: E1-1 | F12: 16 c | H12: Financial resources allocated to action plan (CapEx) | I12: monetary | O12: Quantitative | Q12: In scope
A13: E1-1_07 | B13: =IF(ISNUMBER(SEARCH(".IRO",A13)),"Exclude", IF(ISNUMBER(SEARCH(".GOV",A13)),"Exclude", IF(ISNUMBER(SEARCH(".SBM",A13)),"Exclude", IF(ISNUMBER(SEARCH(".MDR",A13)),"Exclude", "Keep")))) -> Keep | C13: E1 | E13: E1-1 | F13: 16 d | G13: AR 3 | H13: Explanation of potential locked-in GHG emissions from key assets and products and of how locked-in GHG emissions may jeopardise achievement of GHG emission reduction targets and drive transition risk | I13: narrative | O13: Qualitative | Q13: In scope
A14: E1-1_08 | B14: =IF(ISNUMBER(SEARCH(".IRO",A14)),"Exclude", IF(ISNUMBER(SEARCH(".GOV",A14)),"Exclude", IF(ISNUMBER(SEARCH(".SBM",A14)),"Exclude", IF(ISNUMBER(SEARCH(".MDR",A14)),"Exclude", "Keep")))) -> Keep | C14: E1 | E14: E1-1 | F14: 16 e | G14: AR 4 | H14: Explanation of any objective or plans (CapEx, CapEx plans, OpEx) for aligning economic activities (revenues, CapEx, OpEx) with criteria established in Commission Delegated Regulation 2021/2139 | I14: narrative | J14: Conditional | O14: Qualitative | Q14: In scope
A15: E1-1_09 | B15: =IF(ISNUMBER(SEARCH(".IRO",A15)),"Exclude", IF(ISNUMBER(SEARCH(".GOV",A15)),"Exclude", IF(ISNUMBER(SEARCH(".SBM",A15)),"Exclude", IF(ISNUMBER(SEARCH(".MDR",A15)),"Exclude", "Keep")))) -> Keep | C15: E1 | E15: E1-1 | F15: 16 f | G15: AR 5 | H15: Significant CapEx for coal-related economic activities | I15: monetary | J15: Conditional | O15: Quantitative | Q15: In scope
A16: E1-1_10 | B16: =IF(ISNUMBER(SEARCH(".IRO",A16)),"Exclude", IF(ISNUMBER(SEARCH(".GOV",A16)),"Exclude", IF(ISNUMBER(SEARCH(".SBM",A16)),"Exclude", IF(ISNUMBER(SEARCH(".MDR",A16)),"Exclude", "Keep")))) -> Keep | C16: E1 | E16: E1-1 | F16: 16 f | G16: AR 5 | H16: Significant CapEx for oil-related economic activities | I16: monetary | J16: Conditional | O16: Quantitative | Q16: In scope
A17: E1-1_11 | B17: =IF(ISNUMBER(SEARCH(".IRO",A17)),"Exclude", IF(ISNUMBER(SEARCH(".GOV",A17)),"Exclude", IF(ISNUMBER(SEARCH(".SBM",A17)),"Exclude", IF(ISNUMBER(SEARCH(".MDR",A17)),"Exclude", "Keep")))) -> Keep | C17: E1 | E17: E1-1 | F17: 16 f | G17: AR 5 | H17: Significant CapEx for gas-related economic activities | I17: monetary | J17: Conditional | O17: Quantitative | Q17: In scope
A18: E1-1_12 | B18: =IF(ISNUMBER(SEARCH(".IRO",A18)),"Exclude", IF(ISNUMBER(SEARCH(".GOV",A18)),"Exclude", IF(ISNUMBER(SEARCH(".SBM",A18)),"Exclude", IF(ISNUMBER(SEARCH(".MDR",A18)),"Exclude", "Keep")))) -> Keep | C18: E1 | E18: E1-1 | F18: 16 g | H18: Undertaking is excluded from EU Paris-aligned Benchmarks | I18: semi-narrative | L18: PILLAR 3 + Benchmark | O18: Qualitative | Q18: In scope
A19: E1-1_13 | B19: =IF(ISNUMBER(SEARCH(".IRO",A19)),"Exclude", IF(ISNUMBER(SEARCH(".GOV",A19)),"Exclude", IF(ISNUMBER(SEARCH(".SBM",A19)),"Exclude", IF(ISNUMBER(SEARCH(".MDR",A19)),"Exclude", "Keep")))) -> Keep | C19: E1 | E19: E1-1 | F19: 16 h | H19: Explanation of how transition plan is embedded in and aligned with overall business strategy and financial planning | I19: narrative | O19: Qualitative | Q19: In scope
A20: E1-1_14 | B20: =IF(ISNUMBER(SEARCH(".IRO",A20)),"Exclude", IF(ISNUMBER(SEARCH(".GOV",A20)),"Exclude", IF(ISNUMBER(SEARCH(".SBM",A20)),"Exclude", IF(ISNUMBER(SEARCH(".MDR",A20)),"Exclude", "Keep")))) -> Keep | C20: E1 | E20: E1-1 | F20: 16 i | H20: Transition plan is approved by administrative, management and supervisory bodies | I20: semi-narrative | O20: Qualitative | Q20: In scope
A21: E1-1_15 | B21: =IF(ISNUMBER(SEARCH(".IRO",A21)),"Exclude", IF(ISNUMBER(SEARCH(".GOV",A21)),"Exclude", IF(ISNUMBER(SEARCH(".SBM",A21)),"Exclude", IF(ISNUMBER(SEARCH(".MDR",A21)),"Exclude", "Keep")))) -> Keep | C21: E1 | E21: E1-1 | F21: 16 j | H21: Explanation of progress in implementing transition plan | I21: narrative | O21: Qualitative | Q21: In scope
A22: E1-1_16 | B22: =IF(ISNUMBER(SEARCH(".IRO",A22)),"Exclude", IF(ISNUMBER(SEARCH(".GOV",A22)),"Exclude", IF(ISNUMBER(SEARCH(".SBM",A22)),"Exclude", IF(ISNUMBER(SEARCH(".MDR",A22)),"Exclude", "Keep")))) -> Keep | C22: E1 | E22: E1-1 | F22: 17 | H22: Date of adoption of transition plan for undertakings not having adopted transition plan yet | I22: gYear | J22: Conditional | O22: Qualitative | Q22: In scope
A23: E1.SBM-3_01 | B23: =IF(ISNUMBER(SEARCH(".IRO",A23)),"Exclude", IF(ISNUMBER(SEARCH(".GOV",A23)),"Exclude", IF(ISNUMBER(SEARCH(".SBM",A23)),"Exclude", IF(ISNUMBER(SEARCH(".MDR",A23)),"Exclude", "Keep")))) -> Exclude | C23: E1 | E23: E1.SBM-3 | F23: 18 | H23: Type of climate-related risk | I23: semi-narrative | O23: Qualitative | Q23: In scope
A24: E1.SBM-3_02 | B24: =IF(ISNUMBER(SEARCH(".IRO",A24)),"Exclude", IF(ISNUMBER(SEARCH(".GOV",A24)),"Exclude", IF(ISNUMBER(SEARCH(".SBM",A24)),"Exclude", IF(ISNUMBER(SEARCH(".MDR",A24)),"Exclude", "Keep")))) -> Exclude | C24: E1 | E24: E1.SBM-3 | F24: 19 a | G24: AR 6, AR 13 | H24: Description of scope of resilience analysis | I24: narrative | O24: Qualitative | Q24: In scope
A25: E1.SBM-3_03 | B25: =IF(ISNUMBER(SEARCH(".IRO",A25)),"Exclude", IF(ISNUMBER(SEARCH(".GOV",A25)),"Exclude", IF(ISNUMBER(SEARCH(".SBM",A25)),"Exclude", IF(ISNUMBER(SEARCH(".MDR",A25)),"Exclude", "Keep")))) -> Exclude | C25: E1 | E25: E1.SBM-3 | F25: 19 b | G25: AR 7a, AR 13 | H25: Disclosure of how resilience analysis has been conducted | I25: narrative | O25: Qualitative | Q25: In scope
A26: E1.SBM-3_04 | B26: =IF(ISNUMBER(SEARCH(".IRO",A26)),"Exclude", IF(ISNUMBER(SEARCH(".GOV",A26)),"Exclude", IF(ISNUMBER(SEARCH(".SBM",A26)),"Exclude", IF(ISNUMBER(SEARCH(".MDR",A26)),"Exclude", "Keep")))) -> Exclude | C26: E1 | E26: E1.SBM-3 | F26: 19 b | G26: AR 7a, AR 13 | H26: Disclosure of how resilience analysis has been conducted | I26: date | O26: Qualitative | Q26: In scope
A27: E1.SBM-3_05 | B27: =IF(ISNUMBER(SEARCH(".IRO",A27)),"Exclude", IF(ISNUMBER(SEARCH(".GOV",A27)),"Exclude", IF(ISNUMBER(SEARCH(".SBM",A27)),"Exclude", IF(ISNUMBER(SEARCH(".MDR",A27)),"Exclude", "Keep")))) -> Exclude | C27: E1 | E27: E1.SBM-3 | F27: AR 7b | H27: Time horizons applied for resilience analysis | I27: semi-narrative | O27: Qualitative | Q27: In scope
A28: E1.SBM-3_06 | B28: =IF(ISNUMBER(SEARCH(".IRO",A28)),"Exclude", IF(ISNUMBER(SEARCH(".GOV",A28)),"Exclude", IF(ISNUMBER(SEARCH(".SBM",A28)),"Exclude", IF(ISNUMBER(SEARCH(".MDR",A28)),"Exclude", "Keep")))) -> Exclude | C28: E1 | E28: E1.SBM-3 | F28: 19 c | G28: AR 8a, AR 13 | H28: Description of results of resilience analysis | I28: narrative | O28: Qualitative | Q28: In scope
A29: E1.SBM-3_07 | B29: =IF(ISNUMBER(SEARCH(".IRO",A29)),"Exclude", IF(ISNUMBER(SEARCH(".GOV",A29)),"Exclude", IF(ISNUMBER(SEARCH(".SBM",A29)),"Exclude", IF(ISNUMBER(SEARCH(".MDR",A29)),"Exclude", "Keep")))) -> Exclude | C29: E1 | E29: E1.SBM-3 | F29: AR 8 b | H29: Description of ability to adjust or adapt strategy and business model to climate change | I29: narrative | O29: Qualitative | Q29: In scope
A30: E1.IRO-1_01 | B30: =IF(ISNUMBER(SEARCH(".IRO",A30)),"Exclude", IF(ISNUMBER(SEARCH(".GOV",A30)),"Exclude", IF(ISNUMBER(SEARCH(".SBM",A30)),"Exclude", IF(ISNUMBER(SEARCH(".MDR",A30)),"Exclude", "Keep")))) -> Exclude | C30: E1 | E30: E1.IRO-1 | F30: 20 a, AR 9 | G30: AR 10 | H30: Description of process in relation to impacts on climate change | I30: narrative | O30: Qualitative | Q30: In scope
A31: E1.IRO-1_02 | B31: =IF(ISNUMBER(SEARCH(".IRO",A31)),"Exclude", IF(ISNUMBER(SEARCH(".GOV",A31)),"Exclude", IF(ISNUMBER(SEARCH(".SBM",A31)),"Exclude", IF(ISNUMBER(SEARCH(".MDR",A31)),"Exclude", "Keep")))) -> Exclude | C31: E1 | E31: E1.IRO-1 | F31: 20 b | G31: AR 13-AR 14 | H31: Description of process in relation to climate-related physical risks in own operations and along value chain | I31: narrative | O31: Qualitative | Q31: In scope
A32: E1.IRO-1_03 | B32: =IF(ISNUMBER(SEARCH(".IRO",A32)),"Exclude", IF(ISNUMBER(SEARCH(".GOV",A32)),"Exclude", IF(ISNUMBER(SEARCH(".SBM",A32)),"Exclude", IF(ISNUMBER(SEARCH(".MDR",A32)),"Exclude", "Keep")))) -> Exclude | C32: E1 | E32: E1.IRO-1 | F32: AR 11 a | G32: AR 13-AR 14 | H32: Climate-related hazards have been identified over short-, medium- and long-term time horizons | I32: semi-narrative | O32: Qualitative | Q32: In scope
A33: E1.IRO-1_04 | B33: =IF(ISNUMBER(SEARCH(".IRO",A33)),"Exclude", IF(ISNUMBER(SEARCH(".GOV",A33)),"Exclude", IF(ISNUMBER(SEARCH(".SBM",A33)),"Exclude", IF(ISNUMBER(SEARCH(".MDR",A33)),"Exclude", "Keep")))) -> Exclude | C33: E1 | E33: E1.IRO-1 | F33: AR 11 a | G33: AR 13-AR 14 | H33: Undertaking has screened whether assets and business activities may be exposed to climate-related hazards | I33: semi-narrative | O33: Qualitative | Q33: In scope
A34: E1.IRO-1_05 | B34: =IF(ISNUMBER(SEARCH(".IRO",A34)),"Exclude", IF(ISNUMBER(SEARCH(".GOV",A34)),"Exclude", IF(ISNUMBER(SEARCH(".SBM",A34)),"Exclude", IF(ISNUMBER(SEARCH(".MDR",A34)),"Exclude", "Keep")))) -> Exclude | C34: E1 | E34: E1.IRO-1 | F34: AR 11 b | G34: AR 13-AR 14 | H34: Short-, medium- and long-term time horizons have been defined | I34: semi-narrative | O34: Qualitative | Q34: In scope
A35: E1.IRO-1_06 | B35: =IF(ISNUMBER(SEARCH(".IRO",A35)),"Exclude", IF(ISNUMBER(SEARCH(".GOV",A35)),"Exclude", IF(ISNUMBER(SEARCH(".SBM",A35)),"Exclude", IF(ISNUMBER(SEARCH(".MDR",A35)),"Exclude", "Keep")))) -> Exclude | C35: E1 | E35: E1.IRO-1 | F35: AR 11 c | G35: AR 13-AR 14 | H35: Extent to which assets and business activities may be exposed and are sensitive to identified climate-related hazards has been assessed | I35: semi-narrative | O35: Qualitative | Q35: In scope
A36: E1.IRO-1_07 | B36: =IF(ISNUMBER(SEARCH(".IRO",A36)),"Exclude", IF(ISNUMBER(SEARCH(".GOV",A36)),"Exclude", IF(ISNUMBER(SEARCH(".SBM",A36)),"Exclude", IF(ISNUMBER(SEARCH(".MDR",A36)),"Exclude", "Keep")))) -> Exclude | C36: E1 | E36: E1.IRO-1 | F36: AR 11 d | G36: AR 13-AR 14 | H36: Identification of climate-related hazards and assessment of exposure and sensitivity are informed by high emissions climate scenarios | I36: semi-narrative | O36: Qualitative | Q36: In scope
A37: E1.IRO-1_08 | B37: =IF(ISNUMBER(SEARCH(".IRO",A37)),"Exclude", IF(ISNUMBER(SEARCH(".GOV",A37)),"Exclude", IF(ISNUMBER(SEARCH(".SBM",A37)),"Exclude", IF(ISNUMBER(SEARCH(".MDR",A37)),"Exclude", "Keep")))) -> Exclude | C37: E1 | E37: E1.IRO-1 | F37: 21 | G37: AR 13-AR 14 | H37: Explanation of how climate-related scenario analysis has been used to inform identification and assessment of physical risks over short, medium and long-term | I37: narrative | O37: Qualitative | Q37: In scope
A38: E1.IRO-1_09 | B38: =IF(ISNUMBER(SEARCH(".IRO",A38)),"Exclude", IF(ISNUMBER(SEARCH(".GOV",A38)),"Exclude", IF(ISNUMBER(SEARCH(".SBM",A38)),"Exclude", IF(ISNUMBER(SEARCH(".MDR",A38)),"Exclude", "Keep")))) -> Exclude | C38: E1 | E38: E1.IRO-1 | F38: 20 c | G38: AR 13-AR 14 | H38: Description of process in relation to climate-related transition risks and opportunities in own operations and along value chain | I38: narrative | O38: Qualitative | Q38: In scope
A39: E1.IRO-1_10 | B39: =IF(ISNUMBER(SEARCH(".IRO",A39)),"Exclude", IF(ISNUMBER(SEARCH(".GOV",A39)),"Exclude", IF(ISNUMBER(SEARCH(".SBM",A39)),"Exclude", IF(ISNUMBER(SEARCH(".MDR",A39)),"Exclude", "Keep")))) -> Exclude | C39: E1 | E39: E1.IRO-1 | F39: AR 12 a | G39: AR 13-AR 14 | H39: Transition events have been identified over short-, medium- and long-term time horizons | I39: semi-narrative | O39: Qualitative | Q39: In scope
A40: E1.IRO-1_11 | B40: =IF(ISNUMBER(SEARCH(".IRO",A40)),"Exclude", IF(ISNUMBER(SEARCH(".GOV",A40)),"Exclude", IF(ISNUMBER(SEARCH(".SBM",A40)),"Exclude", IF(ISNUMBER(SEARCH(".MDR",A40)),"Exclude", "Keep")))) -> Exclude | C40: E1 | E40: E1.IRO-1 | F40: AR 12 a | G40: AR 13-AR 14 | H40: Undertaking has screened whether assets and business activities may be exposed to transition events | I40: semi-narrative | O40: Qualitative | Q40: In scope
A41: E1.IRO-1_12 | B41: =IF(ISNUMBER(SEARCH(".IRO",A41)),"Exclude", IF(ISNUMBER(SEARCH(".GOV",A41)),"Exclude", IF(ISNUMBER(SEARCH(".SBM",A41)),"Exclude", IF(ISNUMBER(SEARCH(".MDR",A41)),"Exclude", "Keep")))) -> Exclude | C41: E1 | E41: E1.IRO-1 | F41: AR 12 b | G41: AR 13-AR 14 | H41: Extent to which assets and business activities may be exposed and are sensitive to identified transition events has been assessed | I41: semi-narrative | O41: Qualitative | Q41: In scope
...

Sheet Mapping_ALLStacked
A1: Company | B1: Topic | C1: DR | D1: Description
A2: Bolton | B2: E1 | C2: E1-1 | D2: Transition plan for climate change mitigation
A3: Bolton | B3: E1 | C3: E1-2 | D3: Policies related to climate change mitigation and adaptation
A4: Bolton | B4: E1 | C4: E1-3 | D4: Actions and resources in relation to climate change policies
A5: Bolton | B5: E1 | C5: E1-4 | D5: Targets related to climate change mitigation and adaptation
A6: Bolton | B6: E1 | C6: E1-5 | D6: Energy consumption and mix
A7: Bolton | B7: E1 | C7: E1-6 | D7: Gross Scopes 1,2, 3 and Total GHG emissions
A8: Bolton | B8: E3 | C8: E3-1 | D8: Policies related to water and marine resources
A9: Bolton | B9: E3 | C9: E3-2 | D9: Actions and resources related to water and marine resources
A10: Bolton | B10: E3 | C10: E3-3 | D10: Targets related to water and marine resources
A11: Bolton | B11: E3 | C11: E3-4 | D11: Water consumption
A12: Bolton | B12: E5 | C12: E5-1 | D12: Policies related to resource use and circular economy
... A228: Profand | B228: E1 | C228: E1-1 | D228: Transition plan for climate change mitigation

Sheet DP_Mapping
A1: Source_Datapoint_ID | B1: Source_Datapoint_Label | C1: Matched_ESRS_Standard | D1: Matched_Disclosure_Requirement | E1: Matched_Official_Datapoint_ID | F1: Matched_Official_Datapoint_Name | G1: Match_Type | H1: Match_Confidence | I1: Reviewer_Check_Needed | J1: Mapping_Rationale | K1: Candidate_2_ID | L1: Candidate_2_Name | M1: Candidate_2_Score
A2: e1_E1-1_Climate_governance_committee | B2: E1-1 Climate governance committee | C2: E1 | D2: E1-1 | E2: E1-1_01 | F2: =_xlfn.XLOOKUP(Table8[[#This Row],[Matched_Official_Datapoint_ID]], ESRS_MASTER!A:A, ESRS_MASTER!H:H, 0,0) -> Disclosure of transition plan for climate change mitigation | G2: Exact / near-exact DR-level semantic match | H2: High | I2: No | J2: DR cue detected: E1-1; Standard cue detected: E1; shared terms: climate, e1; score=0.82; runner-up gap=0.02 | K2: E1-1_02 | L2: Explanation of how targets are compatible with limiting of global warming to one and half degrees Celsius in line with Paris Agreement | M2: 0.79
A3: e1_E1-1_Climate_transition_plan_existe | B3: E1-1 Climate transition plan existe | C3: E1 | D3: E1-1 | E3: E1-1_01 | F3: =_xlfn.XLOOKUP(Table8[[#This Row],[Matched_Official_Datapoint_ID]], ESRS_MASTER!A:A, ESRS_MASTER!H:H, 0,0) -> Disclosure of transition plan for climate change mitigation | G3: Exact / near-exact DR-level semantic match | H3: High | I3: No | J3: DR cue detected: E1-1; Standard cue detected: E1; shared terms: climate, e1, plan, transition; score=0.95; runner-up gap=0.06 | K3: E1-1_13 | L3: Explanation of how transition plan is embedded in and aligned with overall business strategy and financial planning | M3: 0.90
A4: e1_E1-1_Decarbonisation_levers_identif | B4: E1-1 Decarbonisation levers identif | C4: E1 | D4: E1-1 | E4: E1-1_03 | F4: =_xlfn.XLOOKUP(Table8[[#This Row],[Matched_Official_Datapoint_ID]], ESRS_MASTER!A:A, ESRS_MASTER!H:H, 0,0) -> Disclosure of decarbonisation levers and key action | G4: Exact / near-exact DR-level semantic match | H4: High | I4: No | J4: DR cue detected: E1-1; Standard cue detected: E1; shared terms: decarbonisation, e1, levers; score=0.90; runner-up gap=0.01 | K4: E1-1_01 | L4: Disclosure of transition plan for climate change mitigation | M4: 0.89
A5: e1_E1-1_Netzero_commitment | B5: E1-1 Netzero commitment | C5: E1 | D5: E1-1 | E5: E1-1_01 | F5: =_xlfn.XLOOKUP(Table8[[#This Row],[Matched_Official_Datapoint_ID]], ESRS_MASTER!A:A, ESRS_MASTER!H:H, 0,0) -> Disclosure of transition plan for climate change mitigation | G5: Exact / near-exact DR-level semantic match | H5: High | I5: No | J5: DR cue detected: E1-1; Standard cue detected: E1; shared terms: climate, e1; score=0.84; runner-up gap=0.04 | K5: E1-1_07 | L5: Explanation of potential locked-in GHG emissions from key assets and products and of how locked-in GHG emissions may jeopardise achievement of GHG emission reduction targets and drive transition risk | M5: 0.80
A6: e1_E1-1_Paris_alignment_commitment | B6: E1-1 Paris alignment commitment | C6: E1 | D6: E1-1 | E6: E1-1_02 | F6: =_xlfn.XLOOKUP(Table8[[#This Row],[Matched_Official_Datapoint_ID]], ESRS_MASTER!A:A, ESRS_MASTER!H:H, 0,0) -> Explanation of how targets are compatible with limiting of global warming to one and half degrees Celsius in line with Paris Agreement | G6: Exact / near-exact DR-level semantic match | H6: High | I6: No | J6: DR cue detected: E1-1; Standard cue detected: E1; shared terms: agreement, e1, paris; score=0.86; runner-up gap=0.01 | K6: E1-1_12 | L6: Undertaking is excluded from EU Paris-aligned Benchmarks | M6: 0.85
A7: e1_E1-1_SBTi_commitment | B7: E1-1 SBTi commitment | C7: E1 | D7: E1-1 | E7: E1-1_07 | F7: =_xlfn.XLOOKUP(Table8[[#This Row],[Matched_Official_Datapoint_ID]], ESRS_MASTER!A:A, ESRS_MASTER!H:H, 0,0) -> Explanation of potential locked-in GHG emissions from key assets and products and of how locked-in GHG emissions may jeopardise achievement of GHG emission reduction targets and drive transition risk | G7: Exact / near-exact DR-level semantic match | H7: High | I7: No | J7: DR cue detected: E1-1; Standard cue detected: E1; shared terms: e1, emission, reduction, targets; score=0.85; runner-up gap=0.02 | K7: E1-1_02 | L7: Explanation of how targets are compatible with limiting of global warming to one and half degrees Celsius in line with Paris Agreement | M7: 0.83
A8: e1_E1-1_Transition_plan_for_climate_ch | B8: E1-1 Transition plan for climate ch | C8: E1 | D8: E1-1 | E8: E1-1_01 | F8: =_xlfn.XLOOKUP(Table8[[#This Row],[Matched_Official_Datapoint_ID]], ESRS_MASTER!A:A, ESRS_MASTER!H:H, 0,0) -> Disclosure of transition plan for climate change mitigation | G8: Exact / near-exact DR-level semantic match | H8: High | I8: No | J8: DR cue detected: E1-1; Standard cue detected: E1; shared terms: change, climate, e1, mitigation, plan, transition; score=1.03; runner-up gap=0.12 | K8: E1-1_15 | L8: Explanation of progress in implementing transition plan | M8: 0.91
A9: e1_E1-1/E1-3_Estimated_reduction_per_lever | B9: E1-1/E1-3 Estimated reduction per lever | C9: E1 | D9: E1-1 | E9: E1-1_07 | F9: =_xlfn.XLOOKUP(Table8[[#This Row],[Matched_Official_Datapoint_ID]], ESRS_MASTER!A:A, ESRS_MASTER!H:H, 0,0) -> Explanation of potential locked-in GHG emissions from key assets and products and of how locked-in GHG emissions may jeopardise achievement of GHG emission reduction targets and drive transition risk | G9: Exact / near-exact DR-level semantic match | H9: High | I9: No | J9: DR cue detected: E1-1; Standard cue detected: E1; shared terms: e1, emissions, ghg, reduction, transition; score=0.89; runner-up gap=0.02 | K9: E1-1_01 | L9: Disclosure of transition plan for climate change mitigation | M9: 0.87
A10: e1_E1-1/E1-9_TCFDaligned_climate_risk_asses | B10: E1-1/E1-9 TCFDaligned climate risk asses | C10: E1 | D10: E1-1 | E10: E1-1_13 | F10: =_xlfn.XLOOKUP(Table8[[#This Row],[Matched_Official_Datapoint_ID]], ESRS_MASTER!A:A, ESRS_MASTER!H:H, 0,0) -> Explanation of how transition plan is embedded in and aligned with overall business strategy and financial planning | G10: Exact / near-exact DR-level semantic match | H10: High | I10: No | J10: DR cue detected: E1-1; Standard cue detected: E1; shared terms: aligned, e1, is, strategy; score=0.88; runner-up gap=0.02 | K10: E1-1_12 | L10: Undertaking is excluded from EU Paris-aligned Benchmarks | M10: 0.87
A11: e1_E1-2_Climate_and_Environmental_Poli | B11: E1-2 Climate and Environmental Poli | C11: E1 | D11: E1-2 | E11: E1-2_01 | F11: =_xlfn.XLOOKUP(Table8[[#This Row],[Matched_Official_Datapoint_ID]], ESRS_MASTER!A:A, ESRS_MASTER!H:H, 0,0) -> Sustainability matters addressed by policy for climate change | G11: Exact / near-exact DR-level semantic match | H11: High | I11: No | J11: DR cue detected: E1-2; Standard cue detected: E1; shared terms: climate, e1, policy; score=0.84; runner-up gap=0.05 | K11: E1.MDR-P_01-06 | L11: Policies in place to manage its material impacts, risks and opportunities related to climate change mitigation and adaptation [see ESRS 2 MDR-P] | M11: 0.78
A12: e1_E1-2_Climaterelated_IRO_list | B12: E1-2 Climaterelated IRO list | C12: E1 | D12: E1-2 | E12: E1.MDR-P_01-06 | F12: =_xlfn.XLOOKUP(Table8[[#This Row],[Matched_Official_Datapoint_ID]], ESRS_MASTER!A:A, ESRS_MASTER!H:H, 0,0) -> Policies in place to manage its material impacts, risks and opportunities related to climate change mitigation and adaptation [see ESRS 2 MDR-P] | G12: Exact / near-exact DR-level semantic match | H12: High | I12: No | J12: DR cue detected: E1-2; Standard cue detected: E1; shared terms: climate, e1, impacts, opportunities, risks; score=0.84; runner-up gap=0.06 | K12: E1-2_01 | L12: Sustainability matters addressed by policy for climate change | M12: 0.78
A13: e1_E1-2/E1-9_Climaterelated_IRO_identificat | B13: E1-2/E1-9 Climaterelated IRO identificat | C13: E1 | D13: E1-2 | E13: E1.MDR-P_01-06 | F13: =_xlfn.XLOOKUP(Table8[[#This Row],[Matched_Official_Datapoint_ID]], ESRS_MASTER!A:A, ESRS_MASTER!H:H, 0,0) -> Policies in place to manage its material impacts, risks and opportunities related to climate change mitigation and adaptation [see ESRS 2 MDR-P] | G13: Exact / near-exact DR-level semantic match | H13: High | I13: No | J13: DR cue detected: E1-2; Standard cue detected: E1; shared terms: adaptation, climate, e1, impacts, mitigation, opportunities, risks; score=0.97; runner-up gap=0.16 | K13: E1-2_01 | L13: Sustainability matters addressed by policy for climate change | M13: 0.81
... A276: g1_G1-6_Payment_practices | B276: G1-6 Payment practices | C276: G1 | D276: G1-6 | E276: G1-6_05 | F276: =_xlfn.XLOOKUP(Table8[[#This Row],[Matched_Official_Datapoint_ID]], ESRS_MASTER!A:A, ESRS_MASTER!H:H, 0,0) -> Disclosure of contextual information regarding payment practices | G276: Exact / near-exact DR-level semantic match | H276: High | I276: No | J276: DR cue detected: G1-6; Standard cue detected: G1; shared terms: g1, payment, practices; score=0.96; runner-up gap=0.11 | K276: G1-6_03 | L276: Percentage of payments aligned with standard payment terms | M276: 0.85
A277: g1_G1/entity-specific_Animal_welfare_as_material_gov | B277: G1/entity-specific Animal welfare as material gov | F277: =_xlfn.XLOOKUP(Table8[[#This Row],[Matched_Official_Datapoint_ID]], ESRS_MASTER!A:A, ESRS_MASTER!H:H, 0,0) -> 0 | G277: No reliable official datapoint match | H277: Low | I277: Yes | J277: Standard cue detected: G1; shared terms: g1; score=0.22; runner-up gap=0.00 | K277: G1.MDR-A_13-14 | L277: Disclosures to be reported if the undertaking has not adopted actions | M277: 0.22
A278: s1_S1-1_Diversity_and_inclusion_approa | B278: S1-1 Diversity and inclusion approa | C278: S1 | D278: S1-1 | E278: S1-1_12 | F278: =_xlfn.XLOOKUP(Table8[[#This Row],[Matched_Official_Datapoint_ID]], ESRS_MASTER!A:A, ESRS_MASTER!H:H, 0,0) -> Disclosure of specific policy commitments related to inclusion and (or) positive action for people from groups at particular risk of vulnerability in own workforce | G278: Exact / near-exact DR-level semantic match | H278: High | I278: No | J278: DR cue detected: S1-1; Standard cue detected: S1; shared terms: inclusion, people, policy, s1, workforce; score=0.91; runner-up gap=0.00 | K278: S1-1_05 | L278: Disclosure of general approach in relation to engagement with people in its own workforce | M278: 0.90
A279: s1_S1-1_Health_and_safety_policy | B279: S1-1 Health and safety policy | C279: S1 | D279: S1-1 | E279: S1-1_18 | F279: =_xlfn.XLOOKUP(Table8[[#This Row],[Matched_Official_Datapoint_ID]], ESRS_MASTER!A:A, ESRS_MASTER!H:H, 0,0) -> Adjustments to the physical environment to ensure health and safety for workers, customers and other visitors with disabilities are in place | G279: Exact / near-exact DR-level semantic match | H279: High | I279: No | J279: DR cue detected: S1-1; Standard cue detected: S1; shared terms: environment, health, s1, safety; score=0.90; runner-up gap=0.02 | K279: S1-1_03 | L279: Description of relevant human rights policy commitments relevant to own workforce | M279: 0.88
A280: s1_S1-1_Human_Rights_Policy_and_Code_o | B280: S1-1 Human Rights Policy and Code o | C280: S1 | D280: S1-1 | E280: S1-1_03 | F280: =_xlfn.XLOOKUP(Table8[[#This Row],[Matched_Official_Datapoint_ID]], ESRS_MASTER!A:A, ESRS_MASTER!H:H, 0,0) -> Description of relevant human rights policy commitments relevant to own workforce | G280: Exact / near-exact DR-level semantic match | H280: High | I280: No | J280: DR cue detected: S1-1; Standard cue detected: S1; shared terms: human, policy, rights, s1; score=0.94; runner-up gap=0.07 | K280: S1-1_04 | L280: Disclosure of general approach in relation to respect for human rights including labour rights, of people in its own workforce | M280: 0.87
A281: s1_S1-1_Safety_policy | B281: S1-1 Safety policy | C281: S1 | D281: S1-1 | E281: S1-1_03 | F281: =_xlfn.XLOOKUP(Table8[[#This Row],[Matched_Official_Datapoint_ID]], ESRS_MASTER!A:A, ESRS_MASTER!H:H, 0,0) -> Description of relevant human rights policy commitments relevant to own workforce | G281: Exact / near-exact DR-level semantic match | H281: High | I281: No | J281: DR cue detected: S1-1; Standard cue detected: S1; shared terms: own, policy, s1, workforce; score=0.92; runner-up gap=0.04 | K281: S1-1_12 | L281: Disclosure of specific policy commitments related to inclusion and (or) positive action for people from groups at particular risk of vulnerability in own workforce | M281: 0.88
A282: s1_S1-1_Vision_Zero | B282: S1-1 Vision Zero | C282: S1 | D282: S1-1 | E282: S1-1_18 | F282: =_xlfn.XLOOKUP(Table8[[#This Row],[Matched_Official_Datapoint_ID]], ESRS_MASTER!A:A, ESRS_MASTER!H:H, 0,0) -> Adjustments to the physical environment to ensure health and safety for workers, customers and other visitors with disabilities are in place | G282: Exact / near-exact DR-level semantic match | H282: High | I282: No | J282: DR cue detected: S1-1; Standard cue detected: S1; shared terms: s1, safety; score=0.82; runner-up gap=0.03 | K282: S1-1_11 | L282: Grounds for discrimination are specifically covered in policy | M282: 0.79
A283: s1_S1-10/S1-13_GPTW_benchmark_target | B283: S1-10/S1-13 GPTW benchmark target | C283: S1 | D283: S1-10 | E283: S1-10_03 | F283: =_xlfn.XLOOKUP(Table8[[#This Row],[Matched_Official_Datapoint_ID]], ESRS_MASTER!A:A, ESRS_MASTER!H:H, 0,0) -> Percentage of employees paid below the applicable adequate wage benchmark | G283: Exact / near-exact DR-level semantic match | H283: High | I283: No | J283: DR cue detected: S1-10; Standard cue detected: S1; shared terms: 10, benchmark, s1; score=0.84; runner-up gap=0.00 | K283: S1-10_02 | L283: Countries where employees earn below the applicable adequate wage benchmark [table] | M283: 0.84
A284: s1_S1-13_Wellbeing,_health_and_safety_e | B284: S1-13 Wellbeing, health and safety e | C284: S1 | D284: S1-13 | E284: S1-13_05 | F284: =_xlfn.XLOOKUP(Table8[[#This Row],[Matched_Official_Datapoint_ID]], ESRS_MASTER!A:A, ESRS_MASTER!H:H, 0,0) -> Percentage of employees that participated in regular performance and career development reviews by employee category [table] | G284: Exact / near-exact DR-level semantic match | H284: High | I284: No | J284: DR cue detected: S1-13; Standard cue detected: S1; shared terms: 13, employee, s1; score=0.85; runner-up gap=0.00 | K284: S1-13_06 | L284: Average number of employees that participated in regular performance and career development reviews by employee category | M284: 0.85
A285: s1_S1-13/S1-4_Learning/growth_favourable_sco | B285: S1-13/S1-4 Learning/growth favourable sco | C285: S1 | D285: S1-13 | E285: S1-13_04 | F285: =_xlfn.XLOOKUP(Table8[[#This Row],[Matched_Official_Datapoint_ID]], ESRS_MASTER!A:A, ESRS_MASTER!H:H, 0,0) -> Average number of training hours per person for employees | G285: Exact / near-exact DR-level semantic match | H285: High | I285: No | J285: DR cue detected: S1-13; Standard cue detected: S1; shared terms: 13, employees, s1; score=0.90; runner-up gap=0.02 | K285: S1-13_02 | L285: Percentage of employees that participated in regular performance and career development reviews | M285: 0.87
A286: s1_S1-14_Absenteeism | B286: S1-14 Absenteeism | C286: S1 | D286: S1-14 | E286: S1-14_05 | F286: =_xlfn.XLOOKUP(Table8[[#This Row],[Matched_Official_Datapoint_ID]], ESRS_MASTER!A:A, ESRS_MASTER!H:H, 0,0) -> Rate of recordable work-related accidents for own workforce | G286: Exact / near-exact DR-level semantic match | H286: High | I286: No | J286: DR cue detected: S1-14; Standard cue detected: S1; shared terms: 14, rate, s1, workforce; score=1.04; runner-up gap=0.09 | K286: S1-14_04 | L286: Number of recordable work-related accidents for own workforce | M286: 0.94
A287: s1_S1-14_Accident_frequency_rate | B287: S1-14 Accident frequency rate | C287: S1 | D287: S1-14 | E287: S1-14_05 | F287: =_xlfn.XLOOKUP(Table8[[#This Row],[Matched_Official_Datapoint_ID]], ESRS_MASTER!A:A, ESRS_MASTER!H:H, 0,0) -> Rate of recordable work-related accidents for own workforce | G287: Exact / near-exact DR-level semantic match | H287: High | I287: No | J287: DR cue detected: S1-14; Standard cue detected: S1; shared terms: 14, rate, s1; score=0.93; runner-up gap=0.07 | K287: S1-14_04 | L287: Number of recordable work-related accidents for own workforce | M287: 0.85
A288: s1_S1-14_Accident_severity_rate | B288: S1-14 Accident severity rate | C288: S1 | D288: S1-14 | E288: S1-14_05 | F288: =_xlfn.XLOOKUP(Table8[[#This Row],[Matched_Official_Datapoint_ID]], ESRS_MASTER!A:A, ESRS_MASTER!H:H, 0,0) -> Rate of recordable work-related accidents for own workforce | G288: Exact / near-exact DR-level semantic match | H288: High | I288: No | J288: DR cue detected: S1-14; Standard cue detected: S1; shared terms: 14, rate, s1; score=0.94; runner-up gap=0.08 | K288: S1-14_04 | L288: Number of recordable work-related accidents for own workforce | M288: 0.86
A289: s1_S1-14_Fatalities | B289: S1-14 Fatalities | C289: S1 | D289: S1-14 | E289: S1-14_02 | F289: =_xlfn.XLOOKUP(Table8[[#This Row],[Matched_Official_Datapoint_ID]], ESRS_MASTER!A:A, ESRS_MASTER!H:H, 0,0) -> Number of fatalities in own workforce as result of work-related injuries and work-related ill health | G289: Exact / near-exact DR-level semantic match | H289: High | I289: No | J289: DR cue detected: S1-14; Standard cue detected: S1; shared terms: 14, fatalities, health, ill, injuries, number, s1, work; score=1.26; runner-up gap=0.03 | K289: S1-14_07 | L289: Number of days lost to work-related injuries and fatalities from work-related accidents, work-related ill health and fatalities from ill health related to employees | M289: 1.23
... A379: s4_S4-5_Withdrawals_and_recalls | B379: S4-5 Withdrawals and recalls | C379: S4 | D379: S4-5 | E379: S4-5_06 | F379: =_xlfn.XLOOKUP(Table8[[#This Row],[Matched_Official_Datapoint_ID]], ESRS_MASTER!A:A, ESRS_MASTER!H:H, 0,0) -> Disclosure of references to standards or commitments on which target is based | G379: Exact / near-exact DR-level semantic match | H379: High | I379: No | J379: DR cue detected: S4-5; Standard cue detected: S4; shared terms: s4; score=0.79; runner-up gap=0.01 | K379: S4-5_01 | L379: Disclosure of whether and how consumers and end-users were engaged directly in setting targets | M379: 0.79

Sheet Mapping_ALLStacked_TU
A1: Company | B1: Topic | C1: DR | D1: Description
A2: Bolton | B2: E1 | C2: E1-1 | D2: Transition plan for climate change mitigation
A3: Bolton | B3: E1 | C3: E1-2 | D3: Policies related to climate change mitigation and adaptation
A4: Bolton | B4: E1 | C4: E1-3 | D4: Actions and resources in relation to climate change policies
A5: Bolton | B5: E1 | C5: E1-4 | D5: Targets related to climate change mitigation and adaptation
A6: Bolton | B6: E1 | C6: E1-5 | D6: Energy consumption and mix
A7: Bolton | B7: E1 | C7: E1-6 | D7: Gross Scopes 1,2, 3 and Total GHG emissions
A8: Bolton | B8: E3 | C8: E3-1 | D8: Policies related to water and marine resources
A9: Bolton | B9: E3 | C9: E3-2 | D9: Actions and resources related to water and marine resources
A10: Bolton | B10: E3 | C10: E3-3 | D10: Targets related to water and marine resources
A11: Bolton | B11: E3 | C11: E3-4 | D11: Water consumption
A12: Bolton | B12: E5 | C12: E5-1 | D12: Policies related to resource use and circular economy
... A288: Thai Union | B288: E1 | C288: E1-1 | D288: Transition plan for climate change mitigation

Sheet Mapping_ALLStacked_TU_N25
A1: Company | B1: Topic | C1: DR | D1: Description
A2: Bolton | B2: E1 | C2: E1-1 | D2: Transition plan for climate change mitigation
A3: Bolton | B3: E1 | C3: E1-2 | D3: Policies related to climate change mitigation and adaptation
A4: Bolton | B4: E1 | C4: E1-3 | D4: Actions and resources in relation to climate change policies
A5: Bolton | B5: E1 | C5: E1-4 | D5: Targets related to climate change mitigation and adaptation
A6: Bolton | B6: E1 | C6: E1-5 | D6: Energy consumption and mix
A7: Bolton | B7: E1 | C7: E1-6 | D7: Gross Scopes 1,2, 3 and Total GHG emissions
A8: Bolton | B8: E3 | C8: E3-1 | D8: Policies related to water and marine resources
A9: Bolton | B9: E3 | C9: E3-2 | D9: Actions and resources related to water and marine resources
A10: Bolton | B10: E3 | C10: E3-3 | D10: Targets related to water and marine resources
A11: Bolton | B11: E3 | C11: E3-4 | D11: Water consumption
A12: Bolton | B12: E5 | C12: E5-1 | D12: Policies related to resource use and circular economy
... A285: Thai Union | B285: E1 | C285: E1-1 | D285: Transition plan for climate change mitigation

Sheet Mowi_Mapping
A1: Company | B1: Topic | C1: DR / Reference | D1: Datapoint Name | E1: Page Reference | F1: DR Type
A2: Mowi | B2: E1 | C2: E1-1 | D2: Transition plan for climate change mitigation | E2: 96 | F2: Topical DR
A3: Mowi | B3: E1 | C3: E1 IRO-1 | D3: Climate change related risks and opportunities | E3: 99 | F3: Cross-cutting (IRO)
A4: Mowi | B4: E1 | C4: E1-3 | D4: Actions and resources | E4: 101 | F4: Topical DR
A5: Mowi | B5: E1 | C5: E1-4 | D5: Targets and metrics | E5: 102 | F5: Topical DR
A6: Mowi | B6: E1 | C6: E1-5 | D6: Energy consumption and mix | E6: 103 | F6: Topical DR
A7: Mowi | B7: E1 | C7: E1-6 | D7: Gross scopes 1, 2, 3 and total GHG emissions | E7: 104 | F7: Topical DR
A8: Mowi | B8: E3 | C8: E3 SBM-3 | D8: Material impacts, risks, and opportunities related to water and marine resources | E8: 110 | F8: Cross-cutting (SBM)
A9: Mowi | B9: E3 | C9: E3-1 | D9: Management of impacts, risks and opportunities | E9: 112 | F9: Topical DR
A10: Mowi | B10: E3 | C10: E3-2 | D10: Actions and resources | E10: 113 | F10: Topical DR
A11: Mowi | B11: E3 | C11: E3-3 | D11: Targets and metrics | E11: 115 | F11: Topical DR
A12: Mowi | B12: E3 | C12: E3-4 | D12: Water consumption and marine resource performance | E12: 115 | F12: Topical DR
A13: Mowi | B13: E4 | C13: E4-1 | D13: Consideration of biodiversity and ecosystems in strategy and business model | E13: 120 | F13: Topical DR
... A50: Mowi | B50: G1 | C50: G1-4 | D50: Confirmed incidents of corruption or bribery | E50: 164 | F50: Topical DR

Sheet Espersen_Mapping
A1: Company | B1: Topic | C1: DR | D1: Datapoint name | E1: Page reference | F1: Comments | G1: Page reference | H1: Mapping type | I1: Coverage status | J1: Relevance to seafood processing | K1: Business activity flag | L1: Notes on ambiguity
A2: Espersen | B2: E1 | C2: E1-2 | D2: Policies related to climate change mitigation and adaptation | E2: 24
A3: Espersen | B3: E1 | C3: E1-3 | D3: Actions and resources in relation to climate change policies | E3: 27
A4: Espersen | B4: E1 | C4: E1-4 | D4: Targets related to climate change mitigation and adaptation | E4: 26; 87
A5: Espersen | B5: E1 | C5: E1-5 | D5: Energy consumption and mix | E5: 28–29; 89
A6: Espersen | B6: E1 | C6: E1-6 | D6: Gross scopes 1, 2, 3 and total GHG emissions | E6: 25; 86
A7: Espersen | B7: E3 | C7: E3-1 | D7: Policies related to water and marine resources | E7: 30; 32
A8: Espersen | B8: E3 | C8: E3-2 | D8: Actions and resources related to water and marine resources | E8: 30; 33
A9: Espersen | B9: E3 | C9: E3-3 | D9: Targets related to water and marine resources | E9: 32
A10: Espersen | B10: E3 | C10: E3-4 | D10: Water consumption | E10: 90
A11: Espersen | B11: E4 | C11: E4-1 | D11: Transition plan on biodiversity and ecosystems | E11: 34; 36
A12: Espersen | B12: E4 | C12: E4-2 | D12: Policies related to biodiversity and ecosystems | E12: 34; 36
A13: Espersen | B13: E4 | C13: E4-3 | D13: Actions and resources related to biodiversity and ecosystems | E13: 35–36
A14: Espersen | B14: E5 | C14: E5-1 | D14: Policies related to resource use and circular economy | E14: 39; 41
A15: Espersen | B15: E5 | C15: E5-2 | D15: Actions and resources related to resource use and circular economy | E15: 40; 44
A16: Espersen | B16: E5 | C16: E5-3 | D16: Targets related to resource use and circular economy | E16: 39–42
A17: Espersen | B17: E5 | C17: E5-4 | D17: Resource inflows | E17: 37–38
A18: Espersen | B18: E5 | C18: E5-5 | D18: Resource outflows | E18: 41–43
A19: Espersen | B19: S1 | C19: S1-1 | D19: Policies related to own workforce | E19: 48; 50 | F19: Covering only H&S and diversity related topics
A20: Espersen | B20: S1 | C20: S1-4 | D20: Taking action on material impacts on own workforce and approaches to mitigating material risks and pursuing material opportunities and effectiveness of those actions | E20: 46–47
A21: Espersen | B21: S1 | C21: S1-6 | D21: Characteristics of the undertaking’s employees | E21: 91
A22: Espersen | B22: S1 | C22: S1-9 | D22: Diversity metrics | E22: 48–49; 91–92
A23: Espersen | B23: S1 | C23: S1-14 | D23: Health and safety metrics | E23: 51; 93
A24: Espersen | B24: S2 | C24: S2-1 | D24: Policies related to value chain workers | E24: 54
A25: Espersen | B25: S2 | C25: S2-3 | D25: Processes to remediate negative impacts and channels for value chain workers to raise concerns | E25: 55
A26: Espersen | B26: S2 | C26: S2-4 | D26: Taking action on material impacts on value chain workers and approaches to managing material risks and pursuing material opportunities and effectiveness of those actions | E26: 53–54
A27: Espersen | B27: S2 | C27: S2-5 | D27: Targets related to managing material negative impacts advancing positive impacts and managing material risks and opportunities | E27: 54
A28: Espersen | B28: S4 | C28: S4-1 | D28: Policies related to consumers and end-users | E28: 57
A29: Espersen | B29: S4 | C29: S4-2 | D29: Processes for engaging with consumers and end-users about impacts | E29: 60
A30: Espersen | B30: S4 | C30: S4-3 | D30: Processes to remediate negative impacts and channels for consumers and end-users to raise concerns | E30: 61
A31: Espersen | B31: S4 | C31: S4-4 | D31: Taking action on material impacts on consumers and end-users and approaches to managing material risks and pursuing material opportunities and effectiveness of those actions | E31: 58–59
A32: Espersen | B32: S4 | C32: S4-5 | D32: Targets related to managing material negative impacts advancing positive impacts and managing material risks and opportunities | E32: 59
A33: Espersen | B33: G1 | C33: G1-1 | D33: Corporate culture and business conduct policies and corporate culture | E33: 63-64
A34: Espersen | B34: G1 | C34: G1-2 | D34: Management of relationships with suppliers | E34: 67-70
A35: Espersen | B35: G1 | C35: G1-3 | D35: Prevention and detection of corruption and bribery | E35: 64-65
A36: Espersen | B36: G1 | C36: G1-4 | D36: Confirmed incidents of corruption or bribery | E36: 65
A37: Espersen | B37: G1 | C37: G1-5 | D37: Political influence and lobbying activities | E37: 66

Sheet Espersen2025_Mapping
A1: Company | B1: Topic | C1: DR | D1: Datapoint name | E1: Page reference | F1: Comments
A2: Espersen 2025 | B2: E1 | C2: E1-2 | D2: Policies related to climate change mitigation and adaptation | E2: 24
A3: Espersen 2025 | B3: E1 | C3: E1-3 | D3: Actions and resources in relation to climate change policies | E3: 28
A4: Espersen 2025 | B4: E1 | C4: E1-4 | D4: Targets related to climate change mitigation and adaptation | E4: 26-27, 97
A5: Espersen 2025 | B5: E1 | C5: E1-5 | D5: Energy consumption and mix | E5: 32-33, 99
A6: Espersen 2025 | B6: E1 | C6: E1-6 | D6: Gross scopes 1, 2, 3 and total GHG emissions | E6: 25, 96
A7: Espersen 2025 | B7: E3 | C7: E3-1 | D7: Policies related to water and marine resources | E7: 34, 38
A8: Espersen 2025 | B8: E3 | C8: E3-2 | D8: Actions and resources related to water and marine resources | E8: 34, 38-39
A9: Espersen 2025 | B9: E3 | C9: E3-3 | D9: Targets related to water and marine resources | E9: 38
A10: Espersen 2025 | B10: E3 | C10: E3-4 | D10: Water consumption | E10: 38-39, 100
A11: Espersen 2025 | B11: E4 | C11: E4-1 | D11: Transition plan on biodiversity and ecosystems | E11: 40, 42
A12: Espersen 2025 | B12: E4 | C12: E4-2 | D12: Policies related to biodiversity and ecosystems | E12: 40, 42
A13: Espersen 2025 | B13: E4 | C13: E4-3 | D13: Actions and resources related to biodiversity and ecosystems | E13: 40-42
... A35: Espersen 2025 | B35: G1 | C35: G1-5 | D35: Political influence and lobbying activities | E35: 77

Sheet Bolton_Mapping
A1: Company | B1: Topic | C1: DR | D1: Datapoint name | E1: Page reference | F1: Comments | G1: Coverage status | H1: Relevance to seafood processing | I1: Business activity flag | J1: Notes on ambiguity
A2: Bolton | B2: E1 | C2: E1-1 | D2: Transition plan for climate change mitigation | E2: 60–68
A3: Bolton | B3: E1 | C3: E1-2 | D3: Policies related to climate change mitigation and adaptation | E3: 59
A4: Bolton | B4: E1 | C4: E1-3 | D4: Actions and resources in relation to climate change policies | E4: 60–68
A5: Bolton | B5: E1 | C5: E1-4 | D5: Targets related to climate change mitigation and adaptation | E5: 60
A6: Bolton | B6: E1 | C6: E1-5 | D6: Energy consumption and mix | E6: 77–80
A7: Bolton | B7: E1 | C7: E1-6 | D7: Gross Scopes 1,2, 3 and Total GHG emissions
A8: Bolton | B8: E3 | C8: E3-1 | D8: Policies related to water and marine resources | E8: 112; 120–121
A9: Bolton | B9: E3 | C9: E3-2 | D9: Actions and resources related to water and marine resources | E9: 121–131
A10: Bolton | B10: E3 | C10: E3-3 | D10: Targets related to water and marine resources | E10: 113; 132
A11: Bolton | B11: E3 | C11: E3-4 | D11: Water consumption | E11: 114–116
A12: Bolton | B12: E5 | C12: E5-1 | D12: Policies related to resource use and circular economy | E12: 84–85
A13: Bolton | B13: E5 | C13: E5-2 | D13: Actions and resources related to resource use and circular economy | E13: 86–88
A14: Bolton | B14: E5 | C14: E5-3 | D14: Targets related to resource use and circular economy | E14: 92
A15: Bolton | B15: E5 | C15: E5-4 | D15: Resource inflows | E15: 94–98
A16: Bolton | B16: E5 | C16: E5-5 | D16: Resource outflows | E16: 97; 98–101
A17: Bolton | B17: S1 | C17: S1-1 | D17: Policies related to own workforce | E17: 143
A18: Bolton | B18: S1 | C18: S1-2 | D18: Processes for engaging with own workers and workers’ representatives about impacts | E18: 144–145
A19: Bolton | B19: S1 | C19: S1-3 | D19: Processes to remediate negative impacts and channels for own workers to raise concerns | E19: 145
A20: Bolton | B20: S1 | C20: S1-4 | D20: Taking action on material impacts on own workforce, and approaches to mitigating material risks and pursuing material opportunities related to own workforce, and effectiveness of those actions | E20: 146–147
A21: Bolton | B21: S1 | C21: S1-5 | D21: Targets related to managing material negative impacts, advancing positive impacts, and managing material risks and opportunities | E21: 148–149
A22: Bolton | B22: S1 | C22: S1-6 | D22: Characteristics of the undertaking’s employees | E22: 149–151
A23: Bolton | B23: S1 | C23: S1-7 | D23: Characteristics of non-employee workers in the undertaking’s own workforce | E23: 152
A24: Bolton | B24: S1 | C24: S1-8 | D24: Collective bargaining coverage and social dialogue | E24: 152–153
A25: Bolton | B25: S1 | C25: S1-9 | D25: Diversity metrics | E25: 154
A26: Bolton | B26: S1 | C26: S1-10 | D26: Adequate wages | E26: 155
A27: Bolton | B27: S1 | C27: S1-11 | D27: Social protection | E27: 155–156
A28: Bolton | B28: S1 | C28: S1-12 | D28: Persons with disabilities | E28: 157
A29: Bolton | B29: S1 | C29: S1-13 | D29: Training and skills development metrics | E29: 157–158
A30: Bolton | B30: S1 | C30: S1-14 | D30: Health and safety metrics | E30: 158–159
A31: Bolton | B31: S1 | C31: S1-15 | D31: Work-life balance metrics | E31: 159
A32: Bolton | B32: S1 | C32: S1-17 | D32: Incidents, complaints and severe human rights impacts | E32: 159
A33: Bolton | B33: S2 | C33: S2-1 | D33: Policies related to value chain workers | E33: 163–164
A34: Bolton | B34: S2 | C34: S2-2 | D34: Processes for engaging with value chain workers about impacts | E34: 165–166
A35: Bolton | B35: S2 | C35: S2-3 | D35: Processes to remediate negative impacts and channels for value chain workers to raise concerns | E35: 164
A36: Bolton | B36: S3 | C36: S3-1 | D36: Policies related to affected communities | E36: 163–164
A37: Bolton | B37: S3 | C37: S3-2 | D37: Processes for engaging with affected communities about impacts | E37: 156; 165–167
A38: Bolton | B38: S3 | C38: S3-3 | D38: Processes to remediate negative impacts and channels for affected communities to raise concerns | E38: 164
A39: Bolton | B39: S3 | C39: S3-4 | D39: Taking action on material impacts on affected communities, and approaches to managing material risks and pursuing material opportunities related to affected communities, and effectiveness of those actions | E39: 156; 165–167
A40: Bolton | B40: S3 | C40: S3-5 | D40: Targets related to managing material negative impacts, advancing positive impacts, and managing material risks and opportunities | E40: 148
...

Sheet Profand_Mapping
A1: Company | B1: Topic | C1: DR | D1: Datapoint name | E1: Page reference | F1: Comments
A2: Profand | B2: S1 | C2: S1-6 | D2: Employees | E2: Annex 1
A3: Profand | B3: S1 | C3: S1-7 | D3: Non-employee workers | E3: Work continues to report on this indicator in future version
A4: Profand | B4: G1 | C4: G1-3 | D4: Delegation of responsibility for impact management | E4: 4.4. Compliance, good corporate governance and fiscal transp
A5: Profand | B5: S1 | C5: S1-16 | D5: Total annual compensation ratio | E5: Annex 1
A6: Profand | B6: G1 | C6: G1-1 | D6: Commitments and policies | E6: 2.2. Quality and the customer at the heart of our activity /
A7: Profand | B7: S1 | C7: S1-1 | D7: Commitments and policies | E7: 2.2. Quality and the customer at the heart of our activity /
A8: Profand | B8: S2 | C8: S2-1 | D8: Commitments and policies | E8: 2.2. Quality and the customer at the heart of our activity /
A9: Profand | B9: S3 | C9: S3-1 | D9: Commitments and policies | E9: 2.2. Quality and the customer at the heart of our activity /
A10: Profand | B10: S4 | C10: S4-1 | D10: Commitments and policies | E10: 2.2. Quality and the customer at the heart of our activity /
A11: Profand | B11: G1 | C11: G1-1 | D11: Incorporating commitments and policies | E11: 2.2. Quality and the customer at the heart of our activity /
A12: Profand | B12: S1 | C12: S1-4 | D12: Incorporating commitments and policies | E12: 2.2. Quality and the customer at the heart of our activity /
A13: Profand | B13: S2 | C13: S2-4 | D13: Incorporating commitments and policies | E13: 2.2. Quality and the customer at the heart of our activity /
... A84: Profand | B84: S4 | C84: S4-4 | D84: Cases of non-compliance relating to the health and safety impacts of product and service categories | E84: 2.2. Quality and the customer at the heart of our activity
A85: Profand | B85: S4 | C85: S4-4 | D85: Cases of non-compliance concerning health and safety impacts of product and service categories
A86: Profand | B86: G1 | C86: G1-3 | D86: Communication and training on anti-corruption policies and procedures | E86: 4.4. Compliance, good corporate governance and fiscal transp
A87: Profand | B87: G1 | C87: G1-4 | D87: Confirmed incidents of corruption and measures taken
A88: Profand | B88: S1 | C88: S1-17 | D88: Cases of discrimination and corrective actions taken | E88: 4.2. Protection and respect for human and labor rights
A89: Profand | B89: S1 | C89: S1-1 | D89: Operations and suppliers with significant risk of child labor cases | E89: 4.2. Protection and respect for human and labor rights / 4.4
A90: Profand | B90: S2 | C90: S2-1 | D90: Operations and suppliers with significant risk of child labor cases | E90: 4.2. Protection and respect for human and labor rights / 4.4
A91: Profand | B91: S1 | C91: S1-1 | D91: Operations and suppliers with significant risk of cases of forced or compulsory labor | E91: 4.2. Protection and respect for human and labor rights / 4.4
A92: Profand | B92: S2 | C92: S2-1 | D92: Operations and suppliers with significant risk of cases of forced or compulsory labor | E92: 4.2. Protection and respect for human and labor rights / 4.4
A93: Profand | B93: G1 | C93: G1-5 | D93: Political contributions
A94: Profand | B94: S4 | C94: S4-3 | D94: Substantiated complaints regarding breaches of customer privacy and loss of customer data
A95: Profand | B95: S4 | C95: S4-4 | D95: Substantiated complaints regarding breaches of customer privacy and loss of customer data
A96: Profand | B96: E1 | C96: E1-1 | D96: Transition plan for climate change mitigation | E96: PDF pp.5, 58, 60

Sheet Profand2025_Mapping
A1: Company | B1: Topic | C1: DR | D1: Datapoint name | E1: Page reference
A2: Profand 2025 | B2: S1 | C2: S1-6 | D2: Employees | E2: Annex 1
A3: Profand 2025 | B3: S1 | C3: S1-7 | D3: Workers who are not employees | E3: Work is ongoing to report on this indicator in future versio
A4: Profand 2025 | B4: G1 | C4: G1-3 | D4: Delegation of responsibility for managing impacts | E4: 4.4. We uphold ethical business conduct
A5: Profand 2025 | B5: G1 | C5: G1-1 | D5: Policy commitments | E5: 3.3. Enhancing due diligence / 4.2. We protect and respect h
A6: Profand 2025 | B6: S1 | C6: S1-1 | D6: Policy commitments | E6: 3.3. Enhancing due diligence / 4.2. We protect and respect h
A7: Profand 2025 | B7: S2 | C7: S2-1 | D7: Policy commitments | E7: 3.3. Enhancing due diligence / 4.2. We protect and respect h
A8: Profand 2025 | B8: S3 | C8: S3-1 | D8: Policy commitments | E8: 3.3. Enhancing due diligence / 4.2. We protect and respect h
A9: Profand 2025 | B9: S4 | C9: S4-1 | D9: Policy commitments | E9: 3.3. Enhancing due diligence / 4.2. We protect and respect h
A10: Profand 2025 | B10: G1 | C10: G1-1 | D10: Embedding policy commitments | E10: 2.1. Customers at the center: healthy and sustainable food /
A11: Profand 2025 | B11: S1 | C11: S1-4 | D11: Embedding policy commitments | E11: 2.1. Customers at the center: healthy and sustainable food /
A12: Profand 2025 | B12: S2 | C12: S2-4 | D12: Embedding policy commitments | E12: 2.1. Customers at the center: healthy and sustainable food /
... A84: Profand 2025 | B84: E1 | C84: E1-1 | D84: Transition plan for climate change mitigation | E84: PDF pp.52, 55-57

Sheet Nomad_Mapping
A1: Company | B1: Topic | C1: DR | D1: Datapoint name | E1: Page reference | F1: Comments
A2: Nomad Foods | B2: S1 | C2: S1-6 | D2: Total number of employees | E2: Data tables
A3: Nomad Foods | B3: S1 | C3: S1-6 | D3: Employee breakdown by gender and region | E3: Data tables
A4: Nomad Foods | B4: G1 | C4: G1-3 | D4: Delegation of responsibility | E4: Sustainability governance
A5: Nomad Foods | B5: G1 | C5: G1-1 | D5: Policy commitments for responsible business conduct | E5: Sustainability governance / Code of Business Principles / Su
A6: Nomad Foods | B6: S1 | C6: S1-1 | D6: Policy commitments for responsible business conduct | E6: Sustainability governance / Code of Business Principles / Su
A7: Nomad Foods | B7: S2 | C7: S2-1 | D7: Policy commitments for responsible business conduct | E7: Sustainability governance / Code of Business Principles / Su
A8: Nomad Foods | B8: S3 | C8: S3-1 | D8: Policy commitments for responsible business conduct | E8: Sustainability governance / Code of Business Principles / Su
A9: Nomad Foods | B9: S4 | C9: S4-1 | D9: Policy commitments for responsible business conduct | E9: Sustainability governance / Code of Business Principles / Su
A10: Nomad Foods | B10: G1 | C10: G1-1 | D10: Embedding policy commitments for responsible business conduct | E10: Sustainability governance
A11: Nomad Foods | B11: S1 | C11: S1-4 | D11: Embedding policy commitments for responsible business conduct | E11: Sustainability governance
A12: Nomad Foods | B12: S2 | C12: S2-4 | D12: Embedding policy commitments for responsible business conduct | E12: Sustainability governance
A13: Nomad Foods | B13: S3 | C13: S3-4 | D13: Embedding policy commitments for responsible business conduct | E13: Sustainability governance
... A141: Nomad Foods | B141: E1 | C141: E1-1 | D141: Transition plan for climate change mitigation | E141: PDF p.65

Sheet Nomad2025_Mapping
A1: Company | B1: Topic | C1: DR | D1: Datapoint name | E1: Page reference | F1: Comments
A2: Nomad Foods 2025 | B2: S1 | C2: S1-6 | D2: Total number of employees | E2: ESG databook
A3: Nomad Foods 2025 | B3: S1 | C3: S1-6 | D3: Employee breakdown by gender and region | E3: ESG databook
A4: Nomad Foods 2025 | B4: G1 | C4: G1-3 | D4: Delegation of responsibility | E4: Sustainability governance
A5: Nomad Foods 2025 | B5: G1 | C5: G1-1 | D5: Policy commitments for responsible business conduct | E5: Sustainability governance / Code of Business Principles / Su
A6: Nomad Foods 2025 | B6: S1 | C6: S1-1 | D6: Policy commitments for responsible business conduct | E6: Sustainability governance / Code of Business Principles / Su
A7: Nomad Foods 2025 | B7: S2 | C7: S2-1 | D7: Policy commitments for responsible business conduct | E7: Sustainability governance / Code of Business Principles / Su
A8: Nomad Foods 2025 | B8: S3 | C8: S3-1 | D8: Policy commitments for responsible business conduct | E8: Sustainability governance / Code of Business Principles / Su
A9: Nomad Foods 2025 | B9: S4 | C9: S4-1 | D9: Policy commitments for responsible business conduct | E9: Sustainability governance / Code of Business Principles / Su
A10: Nomad Foods 2025 | B10: G1 | C10: G1-1 | D10: Embedding policy commitments for responsible business conduct | E10: Sustainability governance
A11: Nomad Foods 2025 | B11: S1 | C11: S1-4 | D11: Embedding policy commitments for responsible business conduct | E11: Sustainability governance
A12: Nomad Foods 2025 | B12: S2 | C12: S2-4 | D12: Embedding policy commitments for responsible business conduct | E12: Sustainability governance
A13: Nomad Foods 2025 | B13: S3 | C13: S3-4 | D13: Embedding policy commitments for responsible business conduct | E13: Sustainability governance
... A152: Nomad Foods 2025 | B152: E1 | C152: E1-1 | D152: Transition plan for climate change mitigation | E152: PDF pp.35-36

Sheet ThaiUnion_Mapping
A1: Company | B1: Topic | C1: DR | D1: Datapoint name | E1: Page reference | F1: Comments
